Workbook

Sheet input
A1: Anno | B1: 2024 | C1: 2023 | D1: 2022 | E1: 2021 | F1: 2020 | G1: 2019 | H1: 2018 | I1: 2017 | J1: 2016 | K1: 2015
A2: A. CREDITI VERSO SOCI | B2: 0 | C2: 0 | D2: 0 | E2: 0 | F2: 0 | G2: 0 | H2: 0 | I2: 0 | J2: 0 | K2: 0
A3: Quota di capitale richiamata | B3: 0 | C3: 0 | D3: 0 | E3: 0 | F3: 0 | G3: 0 | H3: 0 | I3: 0 | J3: 0 | K3: 0
A4: B. TOTALE IMMOBILIZZAZIONI sep.ind. Di quelle conc. In loc. Finanz. | B4: 3738553 | C4: 3878514 | D4: 3703601 | E4: 3856913 | F4: 4103066 | G4: 2316758 | H4: 2364636 | I4: 2327351 | J4: 2514852 | K4: 2145754
A5: B.I. TOTALE IMMOB. IMMATERIALI | B5: 1282 | C5: 1712 | D5: 2744 | E5: 3344 | F5: 11317 | G5: 23177 | H5: 36257 | I5: 49156 | J5: 62552 | K5: 34512
A6: B.I.1. Costi impianto e ampl. | B6: 0 | C6: 0 | D6: 0 | E6: 0 | F6: 0 | G6: 0 | H6: 0 | I6: 0 | J6: 0 | K6: 0
A7: B.I.2. Costi ricerca e pubb. | B7: 0 | C7: 0 | D7: 0 | E7: 0 | F7: 0 | G7: 0 | H7: 0 | I7: 0 | J7: 0 | K7: 0
A8: B.I.3. Diritti brevetto ind. | B8: 661 | C8: 1049 | D8: 2040 | E8: 3157 | F8: 10942 | G8: 17523 | H8: 25323 | I8: 33879 | J8: 0 | K8: 0
A9: B.I.4. Concessioni, licenze | B9: 621 | C9: 663 | D9: 704 | E9: 0 | F9: 0 | G9: 0 | H9: 0 | I9: 0 | J9: 0 | K9: 0
A10: B.I.5. Avviamento/Differenza di consolidamento | B10: 0 | C10: 0 | D10: 0 | E10: 0 | F10: 0 | G10: 0 | H10: 0 | I10: 0 | J10: 0 | K10: 0
A11: di cui: Avviamento | B11: 0 | C11: 0 | D11: 0 | E11: 0 | F11: 0 | G11: 0 | H11: 0 | I11: 0 | J11: 0 | K11: 0
A12: B.I.6. Imm. in corso | B12: 0 | C12: 0 | D12: 0 | E12: 0 | F12: 0 | G12: 0 | H12: 0 | I12: 0 | J12: 0 | K12: 0
... A93: TOTALE ATTIVO | B93: 6479233 | C93: 6929645 | D93: 6517697 | E93: 6230020 | F93: 6320161 | G93: 4619390 | H93: 4606793 | I93: 4491663 | J93: 4514623 | K93: 4176270
A94: Passivo
A95: PATRIMONIO NETTO
A96: A. TOTALE PATRIMONIO NETTO | B96: 3395702 | C96: 3347713 | D96: 3324149 | E96: 3186130 | F96: 3095198 | G96: 1226155 | H96: 1184635 | I96: 1121927 | J96: 1091757 | K96: 1018727
A97: A.I. Capitale sociale | B97: 110000 | C97: 110000 | D97: 110000 | E97: 110000 | F97: 110000 | G97: 110000 | H97: 110000 | I97: 110000 | J97: 110000 | K97: 110000
A98: di cui: Versamenti soci in c/capitale | B98: 0 | C98: 0 | D98: 0 | E98: 0 | F98: 0 | G98: 0 | H98: 0 | I98: 0 | J98: 0 | K98: 0
A99: di cui: Versamenti in c/futuro aumento di capitale | B99: 0 | C99: 0 | D99: 0 | E99: 0 | F99: 0 | G99: 0 | H99: 0 | I99: 0 | J99: 0 | K99: 0
A100: di cui: Versamenti in c/capitale | B100: 0 | C100: 0 | D100: 0 | E100: 0 | F100: 0 | G100: 0 | H100: 0 | I100: 0 | J100: 0 | K100: 0
A101: di cui: Versamenti a copertura perdite | B101: 0 | C101: 0 | D101: 0 | E101: 0 | F101: 0 | G101: 0 | H101: 0 | I101: 0 | J101: 0 | K101: 0
A102: A.II. Riserva da sovrapprezzo | B102: 0 | C102: 0 | D102: 0 | E102: 0 | F102: 0 | G102: 0 | H102: 0 | I102: 0 | J102: 0 | K102: 0
A103: A.III. Riserva di rivalutazione | B103: 1841883 | C103: 1841883 | D103: 1841883 | E103: 1841883 | F103: 1841883 | G103: 0 | H103: 0 | I103: 0 | J103: 0 | K103: 0
A104: A.IV. Riserva legale | B104: 22000 | C104: 22000 | D104: 22000 | E104: 22000 | F104: 22000 | G104: 22000 | H104: 22000 | I104: 22000 | J104: 22000 | K104: 22000
A105: A.V. Riserva statutaria | B105: 0 | C105: 0 | D105: 0 | E105: 0 | F105: 0 | G105: 0 | H105: 0 | I105: 0 | J105: 0 | K105: 0
A106: Riserva azioni proprie | B106: 0 | C106: 0 | D106: 0 | E106: 0 | F106: 0 | G106: 0 | H106: 0 | I106: 0 | J106: 0 | K106: 0
A107: A.VI. Altre riserve | B107: 240239 | C107: 191213 | D107: 204749 | E107: 204748 | F107: 223037 | G107: 161812 | H107: 161812 | I107: 161812 | J107: 161812 | K107: 161812
... A126: C. TRATTAMENTO DI FINE RAPPORTO | B126: 254425 | C126: 218390 | D126: 277417 | E126: 260333 | F126: 214928 | G126: 226683 | H126: 206901 | I126: 178930 | J126: 182052 | K126: 155271
A127: Debiti
A128: D. TOTALE DEBITI | B128: 2784779 | C128: 3320300 | D128: 2893107 | E128: 2763325 | F128: 2983247 | G128: 3166487 | H128: 3214928 | I128: 3190806 | J128: 3240814 | K128: 2991573
A129: D.1. Obblig.ni entro | B129: 0 | C129: 0 | D129: 0 | E129: 0 | F129: 0 | G129: 0 | H129: 0 | I129: 0 | J129: 0 | K129: 0
A130: D.1. Obblig.ni oltre | B130: 0 | C130: 0 | D130: 0 | E130: 0 | F130: 0 | G130: 0 | H130: 0 | I130: 0 | J130: 0 | K130: 0
A131: D.2. Obblig.ni convert. entro | B131: 0 | C131: 0 | D131: 0 | E131: 0 | F131: 0 | G131: 0 | H131: 0 | I131: 0 | J131: 0 | K131: 0
A132: D.2. Obblig.ni convert. oltre. | B132: 0 | C132: 0 | D132: 0 | E132: 0 | F132: 0 | G132: 0 | H132: 0 | I132: 0 | J132: 0 | K132: 0
A133: D.3. Soci per Finanziamenti entro | B133: 0 | C133: 0 | D133: 0 | E133: 0 | F133: 0 | G133: 0 | H133: 0 | I133: 0 | J133: 0 | K133: 0
A134: D.3. Soci per Finanziamenti oltre | B134: 0 | C134: 0 | D134: 0 | E134: 0 | F134: 0 | G134: 0 | H134: 0 | I134: 0 | J134: 0 | K134: 0
A135: D.4. Banche entro l'esercizio | B135: 760422 | C135: 827770 | D135: 342948 | E135: 283856 | F135: 497144 | G135: 1537431 | H135: 1449053 | I135: 1177500 | J135: 1117556 | K135: 886758
A136: D.4. Banche oltre l'esercizio | B136: 761905 | C136: 1159885 | D136: 1231437 | E136: 1405442 | F136: 1760602 | G136: 787742 | H136: 1000827 | I136: 1175475 | J136: 1379696 | K136: 1316760
A137: D.5. Altri finanziatori entro | B137: 0 | C137: 0 | D137: 0 | E137: 0 | F137: 0 | G137: 0 | H137: 0 | I137: 0 | J137: 0 | K137: 0
A138: D.5. Altri finanziatori oltre | B138: 0 | C138: 0 | D138: 0 | E138: 0 | F138: 0 | G138: 0 | H138: 0 | I138: 0 | J138: 0 | K138: 0
...

Sheet case
A1: SP attivo | B1: =input!B1 -> 2024 | C1: =input!C1 -> 2023 | D1: =input!D1 -> 2022 | E1: =input!E1 -> 2021 | F1: =input!F1 -> 2020 | G1: =input!G1 -> 2019 | H1: =input!H1 -> 2018 | I1: =input!I1 -> 2017 | ... K1: =input!K1 -> 2015 | M1: Segno | N1: Riclassificazione
A2: =input!A2 -> A. CREDITI VERSO SOCI | B2: =$M2*input!B2 -> 0 | C2: =$M2*input!C2 -> 0 | D2: =$M2*input!D2 -> 0 | E2: =$M2*input!E2 -> 0 | F2: =$M2*input!F2 -> 0 | G2: =$M2*input!G2 -> 0 | H2: =$M2*input!H2 -> 0 | I2: =$M2*input!I2 -> 0 | ... K2: =$M2*input!K2 -> 0 | M2: -1 | N2: Finanziamenti netti vs soci e controllanti
A3: =input!A3 -> Quota di capitale richiamata | B3: =$M3*input!B3 -> 0 | C3: =$M3*input!C3 -> 0 | D3: =$M3*input!D3 -> 0 | E3: =$M3*input!E3 -> 0 | F3: =$M3*input!F3 -> 0 | G3: =$M3*input!G3 -> 0 | H3: =$M3*input!H3 -> 0 | I3: =$M3*input!I3 -> 0 | ... K3: =$M3*input!K3 -> 0 | M3: 1
A5: =input!A4 -> B. TOTALE IMMOBILIZZAZIONI sep.ind. Di quelle conc. In loc. Finanz. | B5: =$M5*input!B4 -> 3738553 | C5: =$M5*input!C4 -> 3878514 | D5: =$M5*input!D4 -> 3703601 | E5: =$M5*input!E4 -> 3856913 | F5: =$M5*input!F4 -> 4103066 | G5: =$M5*input!G4 -> 2316758 | H5: =$M5*input!H4 -> 2364636 | I5: =$M5*input!I4 -> 2327351 | ... K5: =$M5*input!K4 -> 2145754 | M5: 1
A6: =input!A5 -> B.I. TOTALE IMMOB. IMMATERIALI | B6: =$M6*input!B5 -> 1282 | C6: =$M6*input!C5 -> 1712 | D6: =$M6*input!D5 -> 2744 | E6: =$M6*input!E5 -> 3344 | F6: =$M6*input!F5 -> 11317 | G6: =$M6*input!G5 -> 23177 | H6: =$M6*input!H5 -> 36257 | I6: =$M6*input!I5 -> 49156 | ... K6: =$M6*input!K5 -> 34512 | M6: 1 | N6: Immobilizzazioni immateriali nette
A7: =input!A6 -> B.I.1. Costi impianto e ampl. | B7: =$M7*input!B6 -> 0 | C7: =$M7*input!C6 -> 0 | D7: =$M7*input!D6 -> 0 | E7: =$M7*input!E6 -> 0 | F7: =$M7*input!F6 -> 0 | G7: =$M7*input!G6 -> 0 | H7: =$M7*input!H6 -> 0 | I7: =$M7*input!I6 -> 0 | ... K7: =$M7*input!K6 -> 0 | M7: 1
A8: =input!A7 -> B.I.2. Costi ricerca e pubb. | B8: =$M8*input!B7 -> 0 | C8: =$M8*input!C7 -> 0 | D8: =$M8*input!D7 -> 0 | E8: =$M8*input!E7 -> 0 | F8: =$M8*input!F7 -> 0 | G8: =$M8*input!G7 -> 0 | H8: =$M8*input!H7 -> 0 | I8: =$M8*input!I7 -> 0 | ... K8: =$M8*input!K7 -> 0 | M8: 1
A9: =input!A8 -> B.I.3. Diritti brevetto ind. | B9: =$M9*input!B8 -> 661 | C9: =$M9*input!C8 -> 1049 | D9: =$M9*input!D8 -> 2040 | E9: =$M9*input!E8 -> 3157 | F9: =$M9*input!F8 -> 10942 | G9: =$M9*input!G8 -> 17523 | H9: =$M9*input!H8 -> 25323 | I9: =$M9*input!I8 -> 33879 | ... K9: =$M9*input!K8 -> 0 | M9: 1
A10: =input!A9 -> B.I.4. Concessioni, licenze | B10: =$M10*input!B9 -> 621 | C10: =$M10*input!C9 -> 663 | D10: =$M10*input!D9 -> 704 | E10: =$M10*input!E9 -> 0 | F10: =$M10*input!F9 -> 0 | G10: =$M10*input!G9 -> 0 | H10: =$M10*input!H9 -> 0 | I10: =$M10*input!I9 -> 0 | ... K10: =$M10*input!K9 -> 0 | M10: 1
A11: =input!A10 -> B.I.5. Avviamento/Differenza di consolidamento | B11: =$M11*input!B10 -> 0 | C11: =$M11*input!C10 -> 0 | D11: =$M11*input!D10 -> 0 | E11: =$M11*input!E10 -> 0 | F11: =$M11*input!F10 -> 0 | G11: =$M11*input!G10 -> 0 | H11: =$M11*input!H10 -> 0 | I11: =$M11*input!I10 -> 0 | ... K11: =$M11*input!K10 -> 0 | M11: 1
A12: =input!A11 -> di cui: Avviamento | B12: =$M12*input!B11 -> 0 | C12: =$M12*input!C11 -> 0 | D12: =$M12*input!D11 -> 0 | E12: =$M12*input!E11 -> 0 | F12: =$M12*input!F11 -> 0 | G12: =$M12*input!G11 -> 0 | H12: =$M12*input!H11 -> 0 | I12: =$M12*input!I11 -> 0 | ... K12: =$M12*input!K11 -> 0 | M12: 1
A13: =input!A12 -> B.I.6. Imm. in corso | B13: =$M13*input!B12 -> 0 | C13: =$M13*input!C12 -> 0 | D13: =$M13*input!D12 -> 0 | E13: =$M13*input!E12 -> 0 | F13: =$M13*input!F12 -> 0 | G13: =$M13*input!G12 -> 0 | H13: =$M13*input!H12 -> 0 | I13: =$M13*input!I12 -> 0 | ... K13: =$M13*input!K12 -> 0 | M13: 1
A14: =input!A13 -> B.I.7. Altre immobiliz. Immateriali | B14: =$M14*input!B13 -> 0 | C14: =$M14*input!C13 -> 0 | D14: =$M14*input!D13 -> 0 | E14: =$M14*input!E13 -> 187 | F14: =$M14*input!F13 -> 375 | G14: =$M14*input!G13 -> 5654 | H14: =$M14*input!H13 -> 10934 | I14: =$M14*input!I13 -> 15277 | ... K14: =$M14*input!K13 -> 0 | M14: 1
A15: =input!A14 -> Fondo amm.to Immob. Immateriali | B15: =$M15*input!B14 -> 0 | C15: =$M15*input!C14 -> 0 | D15: =$M15*input!D14 -> 118560 | E15: =$M15*input!E14 -> 117215 | F15: =$M15*input!F14 -> 107873 | G15: =$M15*input!G14 -> 93505 | H15: =$M15*input!H14 -> 79347 | I15: =$M15*input!I14 -> 64882 | ... K15: =$M15*input!K14 -> 42394 | M15: 1
A16: =input!A15 -> B.II. TOTALE IMMOB. MATERIALI | B16: =$M16*input!B15 -> 3603771 | C16: =$M16*input!C15 -> 3742802 | D16: =$M16*input!D15 -> 3566385 | E16: =$M16*input!E15 -> 3648169 | F16: =$M16*input!F15 -> 3886349 | G16: =$M16*input!G15 -> 2087581 | H16: =$M16*input!H15 -> 2124193 | I16: =$M16*input!I15 -> 2173291 | ... K16: =$M16*input!K15 -> 2109242 | M16: 1 | N16: Immobilizzazioni materiali nette
A17: =input!A16 -> di cui: Beni materiali concessi in locazione finanziaria | B17: =$M17*input!B16 -> 0 | C17: =$M17*input!C16 -> 0 | D17: =$M17*input!D16 -> 0 | E17: =$M17*input!E16 -> 0 | F17: =$M17*input!F16 -> 0 | G17: =$M17*input!G16 -> 0 | H17: =$M17*input!H16 -> 0 | I17: =$M17*input!I16 -> 0 | ... K17: =$M17*input!K16 -> 0 | M17: 1
A18: =input!A17 -> B.II.1. Terreni e fabbricati | B18: =$M18*input!B17 -> 2893415 | C18: =$M18*input!C17 -> 2953285 | D18: =$M18*input!D17 -> 2984293 | E18: =$M18*input!E17 -> 3092147 | F18: =$M18*input!F17 -> 3200001 | G18: =$M18*input!G17 -> 1359175 | H18: =$M18*input!H17 -> 1417257 | I18: =$M18*input!I17 -> 1475508 | ... K18: =$M18*input!K17 -> 0 | M18: 1
A19: =input!A18 -> B.II.2. Impianti | B19: =$M19*input!B18 -> 474391 | C19: =$M19*input!C18 -> 508101 | D19: =$M19*input!D18 -> 317950 | E19: =$M19*input!E18 -> 381250 | F19: =$M19*input!F18 -> 461837 | G19: =$M19*input!G18 -> 482335 | H19: =$M19*input!H18 -> 488838 | I19: =$M19*input!I18 -> 570161 | ... K19: =$M19*input!K18 -> 0 | M19: 1
A20: =input!A19 -> B.II.3. Attrez. industriali | B20: =$M20*input!B19 -> 398 | C20: =$M20*input!C19 -> 498 | D20: =$M20*input!D19 -> 697 | E20: =$M20*input!E19 -> 1552 | F20: =$M20*input!F19 -> 2030 | G20: =$M20*input!G19 -> 3465 | H20: =$M20*input!H19 -> 4900 | I20: =$M20*input!I19 -> 6335 | ... K20: =$M20*input!K19 -> 0 | M20: 1
A21: =input!A20 -> B.II.4. Altri beni | B21: =$M21*input!B20 -> 216674 | C21: =$M21*input!C20 -> 262025 | D21: =$M21*input!D20 -> 247367 | E21: =$M21*input!E20 -> 152641 | F21: =$M21*input!F20 -> 211902 | G21: =$M21*input!G20 -> 207968 | H21: =$M21*input!H20 -> 205564 | I21: =$M21*input!I20 -> 114236 | ... K21: =$M21*input!K20 -> 0 | M21: 1
A22: =input!A21 -> B.II.5. Imm. in corso/acconti | B22: =$M22*input!B21 -> 18893 | C22: =$M22*input!C21 -> 18893 | D22: =$M22*input!D21 -> 16078 | E22: =$M22*input!E21 -> 20579 | F22: =$M22*input!F21 -> 10579 | G22: =$M22*input!G21 -> 34638 | H22: =$M22*input!H21 -> 7634 | I22: =$M22*input!I21 -> 7051 | ... K22: =$M22*input!K21 -> 0 | M22: 1
A23: =input!A22 -> Fondo amm.to Immob. Materiali | B23: =$M23*input!B22 -> 0 | C23: =$M23*input!C22 -> 0 | D23: =$M23*input!D22 -> 1987737 | E23: =$M23*input!E22 -> 1727444 | F23: =$M23*input!F22 -> 1533329 | G23: =$M23*input!G22 -> 2413573 | H23: =$M23*input!H22 -> 2278310 | I23: =$M23*input!I22 -> 2040155 | ... K23: =$M23*input!K22 -> 1639566 | M23: 1
A24: =input!A23 -> B.III. TOTALE IMMOB. FINANZIARIE | B24: =$M24*input!B23 -> 133500 | C24: =$M24*input!C23 -> 134000 | D24: =$M24*input!D23 -> 134472 | E24: =$M24*input!E23 -> 205400 | F24: =$M24*input!F23 -> 205400 | G24: =$M24*input!G23 -> 206000 | H24: =$M24*input!H23 -> 204186 | I24: =$M24*input!I23 -> 104904 | ... K24: =$M24*input!K23 -> 2000 | M24: 1
A25: =input!A24 -> di cui: esigibili entro l'esercizio successivo | B25: =$M25*input!B24 -> 1500 | C25: =$M25*input!C24 -> 77000 | D25: =$M25*input!D24 -> 102472 | E25: =$M25*input!E24 -> 173400 | F25: =$M25*input!F24 -> 173400 | G25: =$M25*input!G24 -> 174000 | H25: =$M25*input!H24 -> 202186 | I25: =$M25*input!I24 -> 102904 | ... K25: =$M25*input!K24 -> 0 | M25: 1
A26: =input!A25 -> B.III.1. TOT Partecipazioni | B26: =$M26*input!B25 -> 72000 | C26: =$M26*input!C25 -> 57000 | D26: =$M26*input!D25 -> 32000 | E26: =$M26*input!E25 -> 32000 | F26: =$M26*input!F25 -> 32000 | G26: =$M26*input!G25 -> 32000 | H26: =$M26*input!H25 -> 2000 | I26: =$M26*input!I25 -> 2000 | ... K26: =$M26*input!K25 -> 2000 | M26: 1
A27: =input!A26 -> B.III.1.a. Imprese controllate | B27: =$M27*input!B26 -> 0 | C27: =$M27*input!C26 -> 0 | D27: =$M27*input!D26 -> 0 | E27: =$M27*input!E26 -> 0 | F27: =$M27*input!F26 -> 0 | G27: =$M27*input!G26 -> 0 | H27: =$M27*input!H26 -> 0 | I27: =$M27*input!I26 -> 0 | ... K27: =$M27*input!K26 -> 0 | M27: 1 | N27: Partecipazioni
A28: =input!A27 -> B.III.1.b. Imprese collegate | B28: =$M28*input!B27 -> 0 | C28: =$M28*input!C27 -> 0 | D28: =$M28*input!D27 -> 0 | E28: =$M28*input!E27 -> 0 | F28: =$M28*input!F27 -> 0 | G28: =$M28*input!G27 -> 0 | H28: =$M28*input!H27 -> 0 | I28: =$M28*input!I27 -> 0 | ... K28: =$M28*input!K27 -> 0 | M28: 1 | N28: Partecipazioni
A29: =input!A28 -> B.III.1.c. Imprese controllanti | B29: =$M29*input!B28 -> 0 | C29: =$M29*input!C28 -> 0 | D29: =$M29*input!D28 -> 0 | E29: =$M29*input!E28 -> 0 | F29: =$M29*input!F28 -> 0 | G29: =$M29*input!G28 -> 0 | H29: =$M29*input!H28 -> 0 | I29: =$M29*input!I28 -> 0 | ... K29: =$M29*input!K28 -> 0 | M29: 1 | N29: Azioni proprie e partecipazioni in controllanti
A30: =input!A29 -> B.III.1.d. In imprese sottoposte al controllo delle controllanti | B30: =$M30*input!B29 -> 0 | C30: =$M30*input!C29 -> 0 | D30: =$M30*input!D29 -> 0 | E30: =$M30*input!E29 -> 0 | F30: =$M30*input!F29 -> 0 | G30: =$M30*input!G29 -> 0 | H30: =$M30*input!H29 -> 0 | I30: =$M30*input!I29 -> 0 | ... K30: =$M30*input!K29 -> 0 | M30: 1 | N30: Azioni proprie e partecipazioni in controllanti
A31: =input!A30 -> B.III.1.d.bis. Altre imprese | B31: =$M31*input!B30 -> 72000 | C31: =$M31*input!C30 -> 57000 | D31: =$M31*input!D30 -> 32000 | E31: =$M31*input!E30 -> 32000 | F31: =$M31*input!F30 -> 32000 | G31: =$M31*input!G30 -> 32000 | H31: =$M31*input!H30 -> 2000 | I31: =$M31*input!I30 -> 2000 | ... K31: =$M31*input!K30 -> 2000 | M31: 1 | N31: Partecipazioni
A32: =input!A31 -> B.III.2. TOT CREDITI Imm. Fin. | B32: =$M32*input!B31 -> 61500 | C32: =$M32*input!C31 -> 77000 | D32: =$M32*input!D31 -> 102472 | E32: =$M32*input!E31 -> 173400 | F32: =$M32*input!F31 -> 173400 | G32: =$M32*input!G31 -> 174000 | H32: =$M32*input!H31 -> 202186 | I32: =$M32*input!I31 -> 102904 | ... K32: =$M32*input!K31 -> 0 | M32: 1
A33: =input!A32 -> B.III.2.a. Cred. vs Controllate entro | B33: =$M33*input!B32 -> 0 | C33: =$M33*input!C32 -> 0 | D33: =$M33*input!D32 -> 0 | E33: =$M33*input!E32 -> 0 | F33: =$M33*input!F32 -> 0 | G33: =$M33*input!G32 -> 0 | H33: =$M33*input!H32 -> 0 | I33: =$M33*input!I32 -> 0 | ... K33: =$M33*input!K32 -> 0 | M33: 1 | N33: Crediti vs controllate e collegate
A34: =input!A33 -> B.III.2.a. Cred. vs Controllate oltre | B34: =$M34*input!B33 -> 0 | C34: =$M34*input!C33 -> 0 | D34: =$M34*input!D33 -> 0 | E34: =$M34*input!E33 -> 0 | F34: =$M34*input!F33 -> 0 | G34: =$M34*input!G33 -> 0 | H34: =$M34*input!H33 -> 0 | I34: =$M34*input!I33 -> 0 | ... K34: =$M34*input!K33 -> 0 | M34: 1 | N34: Crediti vs controllate e collegate
A35: =input!A34 -> B.III.2.b. Cred. vs Collegate entro | B35: =$M35*input!B34 -> 0 | C35: =$M35*input!C34 -> 0 | D35: =$M35*input!D34 -> 0 | E35: =$M35*input!E34 -> 0 | F35: =$M35*input!F34 -> 0 | G35: =$M35*input!G34 -> 0 | H35: =$M35*input!H34 -> 0 | I35: =$M35*input!I34 -> 0 | ... K35: =$M35*input!K34 -> 0 | M35: 1 | N35: Crediti vs controllate e collegate
A36: =input!A35 -> B.III.2.b. Cred. vs Collegate oltre | B36: =$M36*input!B35 -> 0 | C36: =$M36*input!C35 -> 0 | D36: =$M36*input!D35 -> 0 | E36: =$M36*input!E35 -> 0 | F36: =$M36*input!F35 -> 0 | G36: =$M36*input!G35 -> 0 | H36: =$M36*input!H35 -> 0 | I36: =$M36*input!I35 -> 0 | ... K36: =$M36*input!K35 -> 0 | M36: 1 | N36: Crediti vs controllate e collegate
A37: =input!A36 -> B.III.2.c. Cred. vs Controllanti entro | B37: =$M37*input!B36 -> 0 | C37: =$M37*input!C36 -> 0 | D37: =$M37*input!D36 -> 0 | E37: =$M37*input!E36 -> 0 | F37: =$M37*input!F36 -> 0 | G37: =$M37*input!G36 -> 0 | H37: =$M37*input!H36 -> 0 | I37: =$M37*input!I36 -> 0 | ... K37: =$M37*input!K36 -> 0 | M37: -1 | N37: Finanziamenti netti vs soci e controllanti
A38: =input!A37 -> B.III.2.c. Cred. vs Controllanti oltre | B38: =$M38*input!B37 -> 0 | C38: =$M38*input!C37 -> 0 | D38: =$M38*input!D37 -> 0 | E38: =$M38*input!E37 -> 0 | F38: =$M38*input!F37 -> 0 | G38: =$M38*input!G37 -> 0 | H38: =$M38*input!H37 -> 0 | I38: =$M38*input!I37 -> 0 | ... K38: =$M38*input!K37 -> 0 | M38: -1 | N38: Finanziamenti netti vs soci e controllanti
A39: =input!A38 -> B.III.2.d. Cred. vs imprese sottoposte al controllo delle controllanti entro | B39: =$M39*input!B38 -> 0 | C39: =$M39*input!C38 -> 0 | D39: =$M39*input!D38 -> 0 | E39: =$M39*input!E38 -> 0 | F39: =$M39*input!F38 -> 0 | G39: =$M39*input!G38 -> 0 | H39: =$M39*input!H38 -> 0 | I39: =$M39*input!I38 -> 0 | ... K39: =$M39*input!K38 -> 0 | M39: -1 | N39: Finanziamenti netti vs soci e controllanti
A40: =input!A39 -> B.III.2.d. Cred. vs imprese sottoposte al controllo delle controllanti oltre | B40: =$M40*input!B39 -> 0 | C40: =$M40*input!C39 -> 0 | D40: =$M40*input!D39 -> 0 | E40: =$M40*input!E39 -> 0 | F40: =$M40*input!F39 -> 0 | G40: =$M40*input!G39 -> 0 | H40: =$M40*input!H39 -> 0 | I40: =$M40*input!I39 -> 0 | ... K40: =$M40*input!K39 -> 0 | M40: -1 | N40: Finanziamenti netti vs soci e controllanti
A41: =input!A40 -> B.III.2.d.bis. Cred. vs Altri entro | B41: =$M41*input!B40 -> 1500 | C41: =$M41*input!C40 -> 77000 | D41: =$M41*input!D40 -> 102472 | E41: =$M41*input!E40 -> 173400 | F41: =$M41*input!F40 -> 173400 | G41: =$M41*input!G40 -> 174000 | H41: =$M41*input!H40 -> 202186 | I41: =$M41*input!I40 -> 102904 | ... K41: =$M41*input!K40 -> 0 | M41: 1 | N41: Crediti diversi
...

Sheet RC
B1: =case!B1 -> 2024 | C1: =case!C1 -> 2023 | D1: =case!D1 -> 2022 | E1: =case!E1 -> 2021 | F1: =case!F1 -> 2020 | G1: =case!G1 -> 2019 | H1: =case!H1 -> 2018 | I1: =case!I1 -> 2017 | ... K1: =case!K1 -> 2015
A2: Stato Patrimoniale Attivo
A3: Attività operative
A4: Attività operative correnti
A5: Crediti verso clienti | B5: =SUMIF(case!$N:$N,$A5,case!B:B) -> 1351939 | C5: =SUMIF(case!$N:$N,$A5,case!C:C) -> 1377676 | D5: =SUMIF(case!$N:$N,$A5,case!D:D) -> 1274814 | E5: =SUMIF(case!$N:$N,$A5,case!E:E) -> 1090084 | F5: =SUMIF(case!$N:$N,$A5,case!F:F) -> 653537 | G5: =SUMIF(case!$N:$N,$A5,case!G:G) -> 1131681 | H5: =SUMIF(case!$N:$N,$A5,case!H:H) -> 945441 | I5: =SUMIF(case!$N:$N,$A5,case!I:I) -> 876265 | J5: =SUMIF(case!$N:$N,$A5,case!J:J) -> 738505 | K5: =SUMIF(case!$N:$N,$A5,case!K:K) -> 795525
A6: Magazzino | B6: =SUMIF(case!$N:$N,$A6,case!B:B) -> 1163582 | C6: =SUMIF(case!$N:$N,$A6,case!C:C) -> 1351255 | D6: =SUMIF(case!$N:$N,$A6,case!D:D) -> 1299305 | E6: =SUMIF(case!$N:$N,$A6,case!E:E) -> 806038 | F6: =SUMIF(case!$N:$N,$A6,case!F:F) -> 1008735 | G6: =SUMIF(case!$N:$N,$A6,case!G:G) -> 996875 | H6: =SUMIF(case!$N:$N,$A6,case!H:H) -> 1101730 | I6: =SUMIF(case!$N:$N,$A6,case!I:I) -> 996728 | J6: =SUMIF(case!$N:$N,$A6,case!J:J) -> 0 | K6: =SUMIF(case!$N:$N,$A6,case!K:K) -> 986831
A7: Altre attività operative correnti | B7: =SUMIF(case!$N:$N,$A7,case!B:B) -> 50404 | C7: =SUMIF(case!$N:$N,$A7,case!C:C) -> 48036 | D7: =SUMIF(case!$N:$N,$A7,case!D:D) -> 36463 | E7: =SUMIF(case!$N:$N,$A7,case!E:E) -> 35592 | F7: =SUMIF(case!$N:$N,$A7,case!F:F) -> 50265 | G7: =SUMIF(case!$N:$N,$A7,case!G:G) -> 42286 | H7: =SUMIF(case!$N:$N,$A7,case!H:H) -> 52754 | I7: =SUMIF(case!$N:$N,$A7,case!I:I) -> 55758 | J7: =SUMIF(case!$N:$N,$A7,case!J:J) -> 61672 | K7: =SUMIF(case!$N:$N,$A7,case!K:K) -> 174082
A8: Totale attività operative correnti | B8: =SUM(B5:B7) -> 2565925 | C8: =SUM(C5:C7) -> 2776967 | D8: =SUM(D5:D7) -> 2610582 | E8: =SUM(E5:E7) -> 1931714 | F8: =SUM(F5:F7) -> 1712537 | G8: =SUM(G5:G7) -> 2170842 | H8: =SUM(H5:H7) -> 2099925 | I8: =SUM(I5:I7) -> 1928751 | ... K8: =SUM(K5:K7) -> 1956438
A9: Immobilizzazioni operative nette
A10: Immobilizzazioni materiali nette | B10: =SUMIF(case!$N:$N,$A10,case!B:B) -> 3603771 | C10: =SUMIF(case!$N:$N,$A10,case!C:C) -> 3742802 | D10: =SUMIF(case!$N:$N,$A10,case!D:D) -> 3566385 | E10: =SUMIF(case!$N:$N,$A10,case!E:E) -> 3648169 | F10: =SUMIF(case!$N:$N,$A10,case!F:F) -> 3886349 | G10: =SUMIF(case!$N:$N,$A10,case!G:G) -> 2087581 | H10: =SUMIF(case!$N:$N,$A10,case!H:H) -> 2124193 | I10: =SUMIF(case!$N:$N,$A10,case!I:I) -> 2173291 | J10: =SUMIF(case!$N:$N,$A10,case!J:J) -> 2247633 | K10: =SUMIF(case!$N:$N,$A10,case!K:K) -> 2109242
A11: Immobilizzazioni immateriali nette | B11: =SUMIF(case!$N:$N,$A11,case!B:B) -> 1282 | C11: =SUMIF(case!$N:$N,$A11,case!C:C) -> 1712 | D11: =SUMIF(case!$N:$N,$A11,case!D:D) -> 2744 | E11: =SUMIF(case!$N:$N,$A11,case!E:E) -> 3344 | F11: =SUMIF(case!$N:$N,$A11,case!F:F) -> 11317 | G11: =SUMIF(case!$N:$N,$A11,case!G:G) -> 23177 | H11: =SUMIF(case!$N:$N,$A11,case!H:H) -> 36257 | I11: =SUMIF(case!$N:$N,$A11,case!I:I) -> 49156 | J11: =SUMIF(case!$N:$N,$A11,case!J:J) -> 62552 | K11: =SUMIF(case!$N:$N,$A11,case!K:K) -> 34512
A12: Totale immobilizzazioni operative nette | B12: =SUM(B10:B11) -> 3605053 | C12: =SUM(C10:C11) -> 3744514 | D12: =SUM(D10:D11) -> 3569129 | E12: =SUM(E10:E11) -> 3651513 | F12: =SUM(F10:F11) -> 3897666 | G12: =SUM(G10:G11) -> 2110758 | H12: =SUM(H10:H11) -> 2160450 | I12: =SUM(I10:I11) -> 2222447 | ... K12: =SUM(K10:K11) -> 2143754
A13: Altre attività operative immobilizzate
A14: Crediti diversi | B14: =SUMIF(case!$N:$N,$A14,case!B:B) -> 61500 | C14: =SUMIF(case!$N:$N,$A14,case!C:C) -> 77000 | D14: =SUMIF(case!$N:$N,$A14,case!D:D) -> 102472 | E14: =SUMIF(case!$N:$N,$A14,case!E:E) -> 173400 | F14: =SUMIF(case!$N:$N,$A14,case!F:F) -> 173400 | G14: =SUMIF(case!$N:$N,$A14,case!G:G) -> 174000 | H14: =SUMIF(case!$N:$N,$A14,case!H:H) -> 202186 | I14: =SUMIF(case!$N:$N,$A14,case!I:I) -> 102904 | J14: =SUMIF(case!$N:$N,$A14,case!J:J) -> 202667 | K14: =SUMIF(case!$N:$N,$A14,case!K:K) -> 0
A15: Totale altre attività operative immobilizzate | B15: =SUM(B14) -> 61500 | C15: =SUM(C14) -> 77000 | D15: =SUM(D14) -> 102472 | E15: =SUM(E14) -> 173400 | F15: =SUM(F14) -> 173400 | G15: =SUM(G14) -> 174000 | H15: =SUM(H14) -> 202186 | I15: =SUM(I14) -> 102904 | ... K15: =SUM(K14) -> 0
A16: Totale attività operative | B16: =B8+B12+B15 -> 6232478 | C16: =C8+C12+C15 -> 6598481 | D16: =D8+D12+D15 -> 6282183 | E16: =E8+E12+E15 -> 5756627 | F16: =F8+F12+F15 -> 5783603 | G16: =G8+G12+G15 -> 4455600 | H16: =H8+H12+H15 -> 4462561 | I16: =I8+I12+I15 -> 4254102 | ... K16: =K8+K12+K15 -> 4100192
A18: Attività fiscali
A19: Crediti fisco-previdenziali | B19: =SUMIF(case!$N:$N,$A19,case!B:B) -> 3863 | C19: =SUMIF(case!$N:$N,$A19,case!C:C) -> 151880 | D19: =SUMIF(case!$N:$N,$A19,case!D:D) -> 118808 | E19: =SUMIF(case!$N:$N,$A19,case!E:E) -> 89563 | F19: =SUMIF(case!$N:$N,$A19,case!F:F) -> 100957 | G19: =SUMIF(case!$N:$N,$A19,case!G:G) -> 88699 | H19: =SUMIF(case!$N:$N,$A19,case!H:H) -> 103085 | I19: =SUMIF(case!$N:$N,$A19,case!I:I) -> 127020 | J19: =SUMIF(case!$N:$N,$A19,case!J:J) -> 133161 | K19: =SUMIF(case!$N:$N,$A19,case!K:K) -> 55816
A20: Attività per imposte anticipate | B20: =SUMIF(case!$N:$N,$A20,case!B:B) -> 0 | C20: =SUMIF(case!$N:$N,$A20,case!C:C) -> 0 | D20: =SUMIF(case!$N:$N,$A20,case!D:D) -> 0 | E20: =SUMIF(case!$N:$N,$A20,case!E:E) -> 0 | F20: =SUMIF(case!$N:$N,$A20,case!F:F) -> 6737 | G20: =SUMIF(case!$N:$N,$A20,case!G:G) -> 0 | H20: =SUMIF(case!$N:$N,$A20,case!H:H) -> 0 | I20: =SUMIF(case!$N:$N,$A20,case!I:I) -> 0 | J20: =SUMIF(case!$N:$N,$A20,case!J:J) -> 0 | K20: =SUMIF(case!$N:$N,$A20,case!K:K) -> 0
A21: Totale attività fiscali | B21: =SUM(B19:B20) -> 3863 | C21: =SUM(C19:C20) -> 151880 | D21: =SUM(D19:D20) -> 118808 | E21: =SUM(E19:E20) -> 89563 | F21: =SUM(F19:F20) -> 107694 | G21: =SUM(G19:G20) -> 88699 | H21: =SUM(H19:H20) -> 103085 | I21: =SUM(I19:I20) -> 127020 | ... K21: =SUM(K19:K20) -> 55816
A23: Attività accessorie
A24: Immobilizzazioni extra-operative | B24: =SUMIF(case!$N:$N,$A24,case!B:B) -> 0 | C24: =SUMIF(case!$N:$N,$A24,case!C:C) -> 0 | D24: =SUMIF(case!$N:$N,$A24,case!D:D) -> 0 | E24: =SUMIF(case!$N:$N,$A24,case!E:E) -> 0 | F24: =SUMIF(case!$N:$N,$A24,case!F:F) -> 0 | G24: =SUMIF(case!$N:$N,$A24,case!G:G) -> 0 | H24: =SUMIF(case!$N:$N,$A24,case!H:H) -> 0 | I24: =SUMIF(case!$N:$N,$A24,case!I:I) -> 0 | J24: =SUMIF(case!$N:$N,$A24,case!J:J) -> 0 | K24: =SUMIF(case!$N:$N,$A24,case!K:K) -> 0
A25: Partecipazioni | B25: =SUMIF(case!$N:$N,$A25,case!B:B) -> 72000 | C25: =SUMIF(case!$N:$N,$A25,case!C:C) -> 57000 | D25: =SUMIF(case!$N:$N,$A25,case!D:D) -> 32000 | E25: =SUMIF(case!$N:$N,$A25,case!E:E) -> 32000 | F25: =SUMIF(case!$N:$N,$A25,case!F:F) -> 32000 | G25: =SUMIF(case!$N:$N,$A25,case!G:G) -> 32000 | H25: =SUMIF(case!$N:$N,$A25,case!H:H) -> 2000 | I25: =SUMIF(case!$N:$N,$A25,case!I:I) -> 2000 | J25: =SUMIF(case!$N:$N,$A25,case!J:J) -> 2000 | K25: =SUMIF(case!$N:$N,$A25,case!K:K) -> 2000
A26: Crediti vs controllate e collegate | B26: =SUMIF(case!$N:$N,$A26,case!B:B) -> 0 | C26: =SUMIF(case!$N:$N,$A26,case!C:C) -> 0 | D26: =SUMIF(case!$N:$N,$A26,case!D:D) -> 0 | E26: =SUMIF(case!$N:$N,$A26,case!E:E) -> 0 | F26: =SUMIF(case!$N:$N,$A26,case!F:F) -> 0 | G26: =SUMIF(case!$N:$N,$A26,case!G:G) -> 0 | H26: =SUMIF(case!$N:$N,$A26,case!H:H) -> 0 | I26: =SUMIF(case!$N:$N,$A26,case!I:I) -> 0 | J26: =SUMIF(case!$N:$N,$A26,case!J:J) -> 0 | K26: =SUMIF(case!$N:$N,$A26,case!K:K) -> 0
A27: Totale attività accessorie | B27: =SUM(B24:B26) -> 72000 | C27: =SUM(C24:C26) -> 57000 | D27: =SUM(D24:D26) -> 32000 | E27: =SUM(E24:E26) -> 32000 | F27: =SUM(F24:F26) -> 32000 | G27: =SUM(G24:G26) -> 32000 | H27: =SUM(H24:H26) -> 2000 | I27: =SUM(I24:I26) -> 2000 | ... K27: =SUM(K24:K26) -> 2000
A29: Attività finanziarie
A30: Riserve strategiche di liquidità | B30: =SUMIF(case!$N:$N,$A30,case!B:B) -> 0 | C30: =SUMIF(case!$N:$N,$A30,case!C:C) -> 0 | D30: =SUMIF(case!$N:$N,$A30,case!D:D) -> 0 | E30: =SUMIF(case!$N:$N,$A30,case!E:E) -> 0 | F30: =SUMIF(case!$N:$N,$A30,case!F:F) -> 0 | G30: =SUMIF(case!$N:$N,$A30,case!G:G) -> 0 | H30: =SUMIF(case!$N:$N,$A30,case!H:H) -> 0 | I30: =SUMIF(case!$N:$N,$A30,case!I:I) -> 0 | J30: =SUMIF(case!$N:$N,$A30,case!J:J) -> 0 | K30: =SUMIF(case!$N:$N,$A30,case!K:K) -> 0
A31: Attività di tesoreria | B31: =SUMIF(case!$N:$N,$A31,case!B:B) -> 170892 | C31: =SUMIF(case!$N:$N,$A31,case!C:C) -> 122284 | D31: =SUMIF(case!$N:$N,$A31,case!D:D) -> 84706 | E31: =SUMIF(case!$N:$N,$A31,case!E:E) -> 351830 | F31: =SUMIF(case!$N:$N,$A31,case!F:F) -> 396864 | G31: =SUMIF(case!$N:$N,$A31,case!G:G) -> 43091 | H31: =SUMIF(case!$N:$N,$A31,case!H:H) -> 39147 | I31: =SUMIF(case!$N:$N,$A31,case!I:I) -> 108541 | J31: =SUMIF(case!$N:$N,$A31,case!J:J) -> 0 | K31: =SUMIF(case!$N:$N,$A31,case!K:K) -> 0
A32: Strumenti derivati attivi | B32: =SUMIF(case!$N:$N,$A32,case!B:B) -> 0 | C32: =SUMIF(case!$N:$N,$A32,case!C:C) -> 0 | D32: =SUMIF(case!$N:$N,$A32,case!D:D) -> 0 | E32: =SUMIF(case!$N:$N,$A32,case!E:E) -> 0 | F32: =SUMIF(case!$N:$N,$A32,case!F:F) -> 0 | G32: =SUMIF(case!$N:$N,$A32,case!G:G) -> 0 | H32: =SUMIF(case!$N:$N,$A32,case!H:H) -> 0 | I32: =SUMIF(case!$N:$N,$A32,case!I:I) -> 0 | J32: =SUMIF(case!$N:$N,$A32,case!J:J) -> 0 | K32: =SUMIF(case!$N:$N,$A32,case!K:K) -> 0
A33: Totale attività finanziarie | B33: =SUM(B30:B32) -> 170892 | C33: =SUM(C30:C32) -> 122284 | D33: =SUM(D30:D32) -> 84706 | E33: =SUM(E30:E32) -> 351830 | F33: =SUM(F30:F32) -> 396864 | G33: =SUM(G30:G32) -> 43091 | H33: =SUM(H30:H32) -> 39147 | I33: =SUM(I30:I32) -> 108541 | ... K33: =SUM(K30:K32) -> 0
A35: Totale attivo | B35: =B16+B21+B27+B33 -> 6479233 | C35: =C16+C21+C27+C33 -> 6929645 | D35: =D16+D21+D27+D33 -> 6517697 | E35: =E16+E21+E27+E33 -> 6230020 | F35: =F16+F21+F27+F33 -> 6320161 | G35: =G16+G21+G27+G33 -> 4619390 | H35: =H16+H21+H27+H33 -> 4606793 | I35: =I16+I21+I27+I33 -> 4491663 | ... K35: =K16+K21+K27+K33 -> 4158008
A37: Check con totale attivo AIDA | B37: =case!B95 -> 6479233 | C37: =case!C95 -> 6929645 | D37: =case!D95 -> 6517697 | E37: =case!E95 -> 6230020 | F37: =case!F95 -> 6320161 | G37: =case!G95 -> 4619390 | H37: =case!H95 -> 4606793 | I37: =case!I95 -> 4491663 | ... K37: =case!K95 -> 4176270
A38: Differenza tra totale attivo e totale attivo AIDA | B38: =B37-B35 -> 0 | C38: =C37-C35 -> 0 | D38: =D37-D35 -> 0 | E38: =E37-E35 -> 0 | F38: =F37-F35 -> 0 | G38: =G37-G35 -> 0 | H38: =H37-H35 -> 0 | I38: =I37-I35 -> 0 | ... K38: =K37-K35 -> 18262
A39: Somma voci spostate nel passivo | B39: =case!B2+case!B46 -> 0 | C39: =case!C2+case!C46 -> 0 | D39: =case!D2+case!D46 -> 0 | E39: =case!E2+case!E46 -> 0 | F39: =case!F2+case!F46 -> 0 | G39: =case!G2+case!G46 -> 0 | H39: =case!H2+case!H46 -> 0 | I39: =case!I2+case!I46 -> 0 | ... K39: =case!K2+case!K46 -> 0
A40: Sbilancio | B40: =B38+B39 -> 0 | C40: =C38+C39 -> 0 | D40: =D38+D39 -> 0 | E40: =E38+E39 -> 0 | F40: =F38+F39 -> 0 | G40: =G38+G39 -> 0 | H40: =H38+H39 -> 0 | I40: =I38+I39 -> 0 | ... K40: =K38+K39 -> 18262
B44: =B1 -> 2024 | C44: =C1 -> 2023 | D44: =D1 -> 2022 | E44: =E1 -> 2021 | F44: =F1 -> 2020 | G44: =G1 -> 2019 | H44: =H1 -> 2018 | I44: =I1 -> 2017 | ... K44: =K1 -> 2015
A45: Stato Patrimoniale Passivo
A46: Passività operative
A47: Passività operative correnti | B47: =SUMIF(case!$N:$N,$A47,case!B:B) -> 0 | C47: =SUMIF(case!$N:$N,$A47,case!C:C) -> 0 | D47: =SUMIF(case!$N:$N,$A47,case!D:D) -> 0 | E47: =SUMIF(case!$N:$N,$A47,case!E:E) -> 0 | F47: =SUMIF(case!$N:$N,$A47,case!F:F) -> 0 | G47: =SUMIF(case!$N:$N,$A47,case!G:G) -> 0 | H47: =SUMIF(case!$N:$N,$A47,case!H:H) -> 0 | I47: =SUMIF(case!$N:$N,$A47,case!I:I) -> 0 | J47: =SUMIF(case!$N:$N,$A47,case!J:J) -> 0 | K47: =SUMIF(case!$N:$N,$A47,case!K:K) -> 0
A48: Debiti vs fornitori | B48: =SUMIF(case!$N:$N,$A48,case!B:B) -> 1001425 | C48: =SUMIF(case!$N:$N,$A48,case!C:C) -> 1022720 | D48: =SUMIF(case!$N:$N,$A48,case!D:D) -> 1073141 | E48: =SUMIF(case!$N:$N,$A48,case!E:E) -> 819126 | F48: =SUMIF(case!$N:$N,$A48,case!F:F) -> 460830 | G48: =SUMIF(case!$N:$N,$A48,case!G:G) -> 618053 | H48: =SUMIF(case!$N:$N,$A48,case!H:H) -> 558934 | I48: =SUMIF(case!$N:$N,$A48,case!I:I) -> 671844 | J48: =SUMIF(case!$N:$N,$A48,case!J:J) -> 578800 | K48: =SUMIF(case!$N:$N,$A48,case!K:K) -> 622035
...

Sheet RF
B1: Rendiconto finanziario | C1: =case!B1 -> 2024 | D1: =case!C1 -> 2023 | E1: =case!D1 -> 2022 | F1: =case!E1 -> 2021 | G1: =case!F1 -> 2020 | H1: =case!G1 -> 2019 | I1: =case!H1 -> 2018 | J1: =case!I1 -> 2017 | ... L1: =case!K1 -> 2015
B2: Flussi di cassa della gestione operativa e accessoria
B3: Flussi di cassa della gestione operativa corrente
A4: + | B4: Reddito operativo | C4: =RC!B131 -> 208796 | D4: =RC!C131 -> 157219 | E4: =RC!D131 -> 237075 | F4: =RC!E131 -> 158900 | G4: =RC!F131 -> 79314 | H4: =RC!G131 -> 101378 | I4: =RC!H131 -> 129035 | J4: =RC!I131 -> 92400 | ... L4: =RC!K131 -> 562402
A5: ± | B5: Reddito gestioni accessoria e straordinaria | C5: =RC!B146 -> 0 | D5: =RC!C146 -> 0 | E5: =RC!D146 -> 0 | F5: =RC!E146 -> 0 | G5: =RC!F146 -> 0 | H5: =RC!G146 -> 0 | I5: =RC!H146 -> 0 | J5: =RC!I146 -> 0 | ... L5: =RC!K146 -> 0
A6: + | B6: Riaggiunta ammortamenti | C6: =-RC!B124 -> 178212 | D6: =-RC!C124 -> 262884 | E6: =-RC!D124 -> 284679 | F6: =-RC!E124 -> 291427 | G6: =-RC!F124 -> 207100 | H6: =-RC!G124 -> 250219 | I6: =-RC!H124 -> 254982 | J6: =-RC!I124 -> 237401 | ... L6: =-RC!K124 -> 190385
A7: - | B7: (Imposte + Risparmio fiscale interessi netti) | C7: =-(RC!B149+RC!B157) -> -4522.7903 | D7: =-(RC!C149+RC!C157) -> -24688.921 | E7: =-(RC!D149+RC!D157) -> 56410.184 | F7: =-(RC!E149+RC!E157) -> 31360.089 | G7: =-(RC!F149+RC!F157) -> 711.47551 | H7: =-(RC!G149+RC!G157) -> 7210.7077 | I7: =-(RC!H149+RC!H157) -> 15690.71 | J7: =-(RC!I149+RC!I157) -> -2098.5248 | ... L7: =-(RC!K149+RC!K157) -> 144205.21
A8: = | B8: EBITDA al netto delle imposte | C8: =C4+C5+C6-C7 -> 391530.79 | D8: =D4+D5+D6-D7 -> 444791.92 | E8: =E4+E5+E6-E7 -> 465343.82 | F8: =F4+F5+F6-F7 -> 418966.91 | G8: =G4+G5+G6-G7 -> 285702.52 | H8: =H4+H5+H6-H7 -> 344386.29 | I8: =I4+I5+I6-I7 -> 368326.29 | J8: =J4+J5+J6-J7 -> 331899.52 | ... L8: =L4+L5+L6-L7 -> 608581.79
B9: Rettifiche per determinare il flusso di cassa
B10: Variazione del CCON*
A11: - | B11: (Aumento) diminuzione crediti verso clienti | C11: =-1*(RC!B5-RC!C5) -> 25737 | D11: =-1*(RC!C5-RC!D5) -> -102862 | E11: =-1*(RC!D5-RC!E5) -> -184730 | F11: =-1*(RC!E5-RC!F5) -> -436547 | G11: =-1*(RC!F5-RC!G5) -> 478144 | H11: =-1*(RC!G5-RC!H5) -> -186240 | I11: =-1*(RC!H5-RC!I5) -> -69176 | J11: =-1*(RC!I5-RC!J5) -> -137760 | ... L11: =-1*(RC!K5-RC!L5) -> -795525
A12: - | B12: (Aumento) diminuzione scorte magazzino | C12: =-1*(RC!B6-RC!C6) -> 187673 | D12: =-1*(RC!C6-RC!D6) -> -51950 | E12: =-1*(RC!D6-RC!E6) -> -493267 | F12: =-1*(RC!E6-RC!F6) -> 202697 | G12: =-1*(RC!F6-RC!G6) -> -11860 | H12: =-1*(RC!G6-RC!H6) -> 104855 | I12: =-1*(RC!H6-RC!I6) -> -105002 | J12: =-1*(RC!I6-RC!J6) -> -996728 | ... L12: =-1*(RC!K6-RC!L6) -> -986831
A13: - | B13: (Aumento) diminuzione altre attività correnti | C13: =-1*(RC!B7-RC!C7) -> -2368 | D13: =-1*(RC!C7-RC!D7) -> -11573 | E13: =-1*(RC!D7-RC!E7) -> -871 | F13: =-1*(RC!E7-RC!F7) -> 14673 | G13: =-1*(RC!F7-RC!G7) -> -7979 | H13: =-1*(RC!G7-RC!H7) -> 10468 | I13: =-1*(RC!H7-RC!I7) -> 3004 | J13: =-1*(RC!I7-RC!J7) -> 5914 | ... L13: =-1*(RC!K7-RC!L7) -> -174082
A14: + | B14: Aumento (diminuzione) debiti verso fornitori | C14: =RC!B48-RC!C48 -> -21295 | D14: =RC!C48-RC!D48 -> -50421 | E14: =RC!D48-RC!E48 -> 254015 | F14: =RC!E48-RC!F48 -> 358296 | G14: =RC!F48-RC!G48 -> -157223 | H14: =RC!G48-RC!H48 -> 59119 | I14: =RC!H48-RC!I48 -> -112910 | J14: =RC!I48-RC!J48 -> 93044 | ... L14: =RC!K48-RC!L48 -> 622035
A15: + | B15: Aumento (diminuzione) altre passività correnti | C15: =RC!B50-RC!C50 -> -32885 | D15: =RC!C50-RC!D50 -> 65057 | E15: =RC!D50-RC!E50 -> -1718 | F15: =RC!E50-RC!F50 -> -6546 | G15: =RC!F50-RC!G50 -> 9954 | H15: =RC!G50-RC!H50 -> 11759 | I15: =RC!H50-RC!I50 -> 24436 | J15: =RC!I50-RC!J50 -> 5953 | ... L15: =RC!K50-RC!L50 -> 10699
A16: - | B16: (Aumento) diminuzione attività fiscali | C16: =-1*(RC!B21-RC!C21) -> 148017 | D16: =-1*(RC!C21-RC!D21) -> -33072 | E16: =-1*(RC!D21-RC!E21) -> -29245 | F16: =-1*(RC!E21-RC!F21) -> 18131 | G16: =-1*(RC!F21-RC!G21) -> -18995 | H16: =-1*(RC!G21-RC!H21) -> 14386 | I16: =-1*(RC!H21-RC!I21) -> 23935 | J16: =-1*(RC!I21-RC!J21) -> 6141 | ... L16: =-1*(RC!K21-RC!L21) -> -55816
A17: + | B17: Aumento (diminuzione) passività fiscali | C17: =RC!B62-RC!C62 -> -14928 | D17: =RC!C62-RC!D62 -> 19505 | E17: =RC!D62-RC!E62 -> -4810 | F17: =RC!E62-RC!F62 -> -9780 | G17: =RC!F62-RC!G62 -> 58179 | H17: =RC!G62-RC!H62 -> 5124 | I17: =RC!H62-RC!I62 -> 16020 | J17: =RC!I62-RC!J62 -> -4728 | ... L17: =RC!K62-RC!L62 -> 72790
A18: = | B18: (Aumento) diminuzione CCON* | C18: =SUM(C11:C17) -> 289951 | D18: =SUM(D11:D17) -> -165316 | E18: =SUM(E11:E17) -> -460626 | F18: =SUM(F11:F17) -> 140924 | G18: =SUM(G11:G17) -> 350220 | H18: =SUM(H11:H17) -> 19471 | I18: =SUM(I11:I17) -> -219693 | J18: =SUM(J11:J17) -> -1028164 | ... L18: =SUM(L11:L17) -> -1306730
A19: + | B19: Aumento (diminuzione) fondo TFR | C19: =RC!B53-RC!C53 -> 36035 | D19: =RC!C53-RC!D53 -> -59027 | E19: =RC!D53-RC!E53 -> 17084 | F19: =RC!E53-RC!F53 -> 45405 | G19: =RC!F53-RC!G53 -> -11755 | H19: =RC!G53-RC!H53 -> 19782 | I19: =RC!H53-RC!I53 -> 27971 | J19: =RC!I53-RC!J53 -> -3122 | ... L19: =RC!K53-RC!L53 -> 155271
A20: - | B20: (Aumento) diminuzione altre attività operative immobilizzate | C20: =-1*(RC!B15-RC!C15) -> 15500 | D20: =-1*(RC!C15-RC!D15) -> 25472 | E20: =-1*(RC!D15-RC!E15) -> 70928 | F20: =-1*(RC!E15-RC!F15) -> 0 | G20: =-1*(RC!F15-RC!G15) -> 600 | H20: =-1*(RC!G15-RC!H15) -> 28186 | I20: =-1*(RC!H15-RC!I15) -> -99282 | J20: =-1*(RC!I15-RC!J15) -> 99763 | ... L20: =-1*(RC!K15-RC!L15) -> 0
A21: + | B21: Aumento (diminuzione) altre passività operative consolidate | C21: =RC!B54-RC!C54 -> 0 | D21: =RC!C54-RC!D54 -> 0 | E21: =RC!D54-RC!E54 -> 0 | F21: =RC!E54-RC!F54 -> 0 | G21: =RC!F54-RC!G54 -> 0 | H21: =RC!G54-RC!H54 -> 0 | I21: =RC!H54-RC!I54 -> 0 | J21: =RC!I54-RC!J54 -> 0 | ... L21: =RC!K54-RC!L54 -> 93230
A22: = | B22: Totale rettifiche | C22: =SUM(C18:C21) -> 341486 | D22: =SUM(D18:D21) -> -198871 | E22: =SUM(E18:E21) -> -372614 | F22: =SUM(F18:F21) -> 186329 | G22: =SUM(G18:G21) -> 339065 | H22: =SUM(H18:H21) -> 67439 | I22: =SUM(I18:I21) -> -291004 | J22: =SUM(J18:J21) -> -931523 | ... L22: =SUM(L18:L21) -> -1058229
A23: = | B23: Flussi di cassa netti gestione operativa corrente, acc e straord. | C23: =C8+C22 -> 733016.79 | D23: =D8+D22 -> 245920.92 | E23: =E8+E22 -> 92729.816 | F23: =F8+F22 -> 605295.91 | G23: =G8+G22 -> 624767.52 | H23: =H8+H22 -> 411825.29 | I23: =I8+I22 -> 77322.29 | J23: =J8+J22 -> -599623.48 | ... L23: =L8+L22 -> -449647.21
B24: Flussi di cassa della gestione investimenti
A25: - | B25: (Aumento) diminuzione Immobilizzazioni operative nette | C25: =-1*(RC!B12-RC!C12) -> 139461 | D25: =-1*(RC!C12-RC!D12) -> -175385 | E25: =-1*(RC!D12-RC!E12) -> 82384 | F25: =-1*(RC!E12-RC!F12) -> 246153 | G25: =-1*(RC!F12-RC!G12) -> -1786908 | H25: =-1*(RC!G12-RC!H12) -> 49692 | I25: =-1*(RC!H12-RC!I12) -> 61997 | J25: =-1*(RC!I12-RC!J12) -> 87738 | ... L25: =-1*(RC!K12-RC!L12) -> -2143754
A26: - | B26: (Aumento) diminuzione attività accessorie | C26: =-1*(RC!B27-RC!C27) -> -15000 | D26: =-1*(RC!C27-RC!D27) -> -25000 | E26: =-1*(RC!D27-RC!E27) -> 0 | F26: =-1*(RC!E27-RC!F27) -> 0 | G26: =-1*(RC!F27-RC!G27) -> 0 | H26: =-1*(RC!G27-RC!H27) -> -30000 | I26: =-1*(RC!H27-RC!I27) -> 0 | J26: =-1*(RC!I27-RC!J27) -> 0 | ... L26: =-1*(RC!K27-RC!L27) -> -2000
A27: + | B27: Aumento (diminuzione) debiti vs controllate e collegate | C27: =RC!B66-RC!C66 -> 0 | D27: =RC!C66-RC!D66 -> 0 | E27: =RC!D66-RC!E66 -> 0 | F27: =RC!E66-RC!F66 -> 0 | G27: =RC!F66-RC!G66 -> 0 | H27: =RC!G66-RC!H66 -> 0 | I27: =RC!H66-RC!I66 -> 0 | J27: =RC!I66-RC!J66 -> 0 | ... L27: =RC!K66-RC!L66 -> 0
A28: - | B28: (Ammortamenti) | C28: =RC!B124 -> -178212 | D28: =RC!C124 -> -262884 | E28: =RC!D124 -> -284679 | F28: =RC!E124 -> -291427 | G28: =RC!F124 -> -207100 | H28: =RC!G124 -> -250219 | I28: =RC!H124 -> -254982 | J28: =RC!I124 -> -237401 | ... L28: =RC!K124 -> -190385
A29: + | B29: Aumento (diminuzione) riserve da rivalutazione | C29: =RC!B80-RC!C80 -> 0 | D29: =RC!C80-RC!D80 -> 0 | E29: =RC!D80-RC!E80 -> 0 | F29: =RC!E80-RC!F80 -> 0 | G29: =RC!F80-RC!G80 -> 1841883 | H29: =RC!G80-RC!H80 -> 0 | I29: =RC!H80-RC!I80 -> 0 | J29: =RC!I80-RC!J80 -> 0 | ... L29: =RC!K80-RC!L80 -> 0
A30: = | B30: Flussi di cassa netti della gestione investimenti | C30: =SUM(C25:C29) -> -53751 | D30: =SUM(D25:D29) -> -463269 | E30: =SUM(E25:E29) -> -202295 | F30: =SUM(F25:F29) -> -45274 | G30: =SUM(G25:G29) -> -152125 | H30: =SUM(H25:H29) -> -230527 | I30: =SUM(I25:I29) -> -192985 | J30: =SUM(J25:J29) -> -149663 | ... L30: =SUM(L25:L29) -> -2336139
A31: = | B31: Free cash flow to the firm (FCFF) | C31: =C23+C30 -> 679265.79 | D31: =D23+D30 -> -217348.08 | E31: =E23+E30 -> -109565.18 | F31: =F23+F30 -> 560021.91 | G31: =G23+G30 -> 472642.52 | H31: =H23+H30 -> 181298.29 | I31: =I23+I30 -> -115662.71 | J31: =J23+J30 -> -749286.48 | ... L31: =L23+L30 -> -2785786.2
B32: Flussi di cassa della gestione finanziaria
B33: Debito e attività finanziarie (esclusa tesoreria)
A34: - | B34: (Oneri finanziari netti) | C34: =RC!B140 -> -108744 | D34: =RC!C140 -> -99460 | E34: =RC!D140 -> -32150 | F34: =RC!E140 -> -28050 | G34: =RC!F140 -> -38589 | H34: =RC!G140 -> -39669 | I34: =RC!H140 -> -38800 | J34: =RC!I140 -> -49795 | ... L34: =RC!K140 -> -60964
A35: + | B35: Risparmio fiscale interessi netti | C35: =-RC!B157 -> -56583.79 | D35: =-RC!C157 -> -58884.921 | E35: =-RC!D157 -> -10496.816 | F35: =-RC!E157 -> -8556.9113 | G35: =-RC!F157 -> -12853.524 | H35: =-RC!G157 -> -12978.292 | I35: =-RC!H157 -> -11836.29 | J35: =-RC!I157 -> -14533.525 | ... L35: =-RC!K157 -> -19958.787
A36: + | B36: Strumenti derivati: (aumento) diminuzione attivi + aumento (diminuzione) passivi | C36: =-(RC!B32-RC!C32)+(RC!B72-RC!C72) -> 0 | D36: =-(RC!C32-RC!D32)+(RC!C72-RC!D72) -> 0 | E36: =-(RC!D32-RC!E32)+(RC!D72-RC!E72) -> 0 | F36: =-(RC!E32-RC!F32)+(RC!E72-RC!F72) -> 0 | G36: =-(RC!F32-RC!G32)+(RC!F72-RC!G72) -> 0 | H36: =-(RC!G32-RC!H32)+(RC!G72-RC!H72) -> 0 | I36: =-(RC!H32-RC!I32)+(RC!H72-RC!I72) -> 0 | J36: =-(RC!I32-RC!J32)+(RC!I72-RC!J72) -> 0 | ... L36: =-(RC!K32-RC!L32)+(RC!K72-RC!L72) -> 0
A37: + | B37: Aumento (diminuzione) debiti struttturali a medio-lungo | C37: =RC!B69-RC!C69 -> -397980 | D37: =RC!C69-RC!D69 -> -71552 | E37: =RC!D69-RC!E69 -> -174005 | F37: =RC!E69-RC!F69 -> -355160 | G37: =RC!F69-RC!G69 -> 972860 | H37: =RC!G69-RC!H69 -> -213085 | I37: =RC!H69-RC!I69 -> -174648 | J37: =RC!I69-RC!J69 -> -204221 | ... L37: =RC!K69-RC!L69 -> 1316760
A38: + | B38: Aumento (diminuzione) debiti strutturali a breve | C38: =RC!B70-RC!C70 -> -67348 | D38: =RC!C70-RC!D70 -> 484822 | E38: =RC!D70-RC!E70 -> 59092 | F38: =RC!E70-RC!F70 -> -213288 | G38: =RC!F70-RC!G70 -> -1040287 | H38: =RC!G70-RC!H70 -> 88378 | I38: =RC!H70-RC!I70 -> 271553 | J38: =RC!I70-RC!J70 -> 59944 | ... L38: =RC!K70-RC!L70 -> 886758
A39: - | B39: (Aumento) diminuzione riserve strategiche di liquidità | C39: =-(RC!B30-RC!C30) -> 0 | D39: =-(RC!C30-RC!D30) -> 0 | E39: =-(RC!D30-RC!E30) -> 0 | F39: =-(RC!E30-RC!F30) -> 0 | G39: =-(RC!F30-RC!G30) -> 0 | H39: =-(RC!G30-RC!H30) -> 0 | I39: =-(RC!H30-RC!I30) -> 0 | J39: =-(RC!I30-RC!J30) -> 0 | ... L39: =-(RC!K30-RC!L30) -> 0
A40: = | B40: Flussi di cassa netti sul debito netto (esclusa tesoreria) (FCDN) | C40: =SUM(C34:C39) -> -630655.79 | D40: =SUM(D34:D39) -> 254925.08 | E40: =SUM(E34:E39) -> -157559.82 | F40: =SUM(F34:F39) -> -605054.91 | G40: =SUM(G34:G39) -> -118869.52 | H40: =SUM(H34:H39) -> -177354.29 | I40: =SUM(I34:I39) -> 46268.71 | J40: =SUM(J34:J39) -> -208605.52 | ... L40: =SUM(L34:L39) -> 2122595.2
...

Sheet ind
A1: INDICATORI FINANZIARI | B1: =RF!C1 -> 2024 | C1: =RF!D1 -> 2023 | D1: =RF!E1 -> 2022 | E1: =RF!F1 -> 2021 | F1: =RF!G1 -> 2020 | G1: =RF!H1 -> 2019 | H1: =RF!I1 -> 2018 | I1: =RF!J1 -> 2017 | ... K1: =RF!L1 -> 2015
A2: valori patrimoniali medie t-1 per attenuare variazioni significativi
A3: RLA (redd. gest OFA) | B3: =RC!B131+RC!B140+RC!B144 -> 100052 | C3: =RC!C131+RC!C140+RC!C144 -> 57759 | D3: =RC!D131+RC!D140+RC!D144 -> 204925 | E3: =RC!E131+RC!E140+RC!E144 -> 130850 | F3: =RC!F131+RC!F140+RC!F144 -> 40725 | G3: =RC!G131+RC!G140+RC!G144 -> 61709 | H3: =RC!H131+RC!H140+RC!H144 -> 90235 | I3: =RC!I131+RC!I140+RC!I144 -> 42605 | ... K3: =RC!K131+RC!K140+RC!K144 -> 501438
A4: Reddito operativo | B4: =RC!B131 -> 208796 | C4: =RC!C131 -> 157219 | D4: =RC!D131 -> 237075 | E4: =RC!E131 -> 158900 | F4: =RC!F131 -> 79314 | G4: =RC!G131 -> 101378 | H4: =RC!H131 -> 129035 | I4: =RC!I131 -> 92400 | ... K4: =RC!K131 -> 562402
A5: EBITDA(MOL) | B5: =RC!B123 -> 425646 | C5: =RC!C123 -> 478043 | D5: =RC!D123 -> 508402 | E5: =RC!E123 -> 485379 | F5: =RC!F123 -> 323613 | G5: =RC!G123 -> 392247 | H5: =RC!H123 -> 423438 | I5: =RC!I123 -> 355258 | ... K5: =RC!K123 -> 792171
A6: Reddito netto | B6: =RC!B150 -> 47991 | C6: =RC!C150 -> 23563 | D6: =RC!D150 -> 138018 | E6: =RC!E150 -> 90933 | F6: =RC!F150 -> 27160 | G6: =RC!G150 -> 41520 | H6: =RC!H150 -> 62708 | I6: =RC!I150 -> 30170 | ... K6: =RC!K150 -> 337274
A7: Ricavi | B7: =RC!B111 -> 10781972 | C7: =RC!C111 -> 10502251 | D7: =RC!D111 -> 9797336 | E7: =RC!E111 -> 8086488 | F7: =RC!F111 -> 7349721 | G7: =RC!G111 -> 8370970 | H7: =RC!H111 -> 7727686 | I7: =RC!I111 -> 7677878 | ... K7: =RC!K111 -> 6901829
A8: Ricavi t-1 | B8: =RC!C111 -> 10502251 | C8: =RC!D111 -> 9797336 | D8: =RC!E111 -> 8086488 | E8: =RC!F111 -> 7349721 | F8: =RC!G111 -> 8370970 | G8: =RC!H111 -> 7727686 | H8: =RC!I111 -> 7677878 | I8: =RC!J111 -> 7424443 | ... K8: =RC!L111 -> 0
A9: Ricavi con IVA gg | B9: =B7*1.22/365 -> 36038.372 | C9: =C7*1.22/365 -> 35103.414 | D9: =D7*1.22/365 -> 32747.26 | E9: =E7*1.22/365 -> 27028.809 | F9: =F7*1.22/365 -> 24566.191 | G9: =G7*1.22/365 -> 27979.681 | H9: =H7*1.22/365 -> 25829.526 | I9: =I7*1.22/365 -> 25663.044 | ... K9: =K7*1.22/365 -> 23069.127
A10: Acquisti | B10: =RC!B116 -> -9103208 | C10: =RC!C116 -> -8982781 | D10: =RC!D116 -> -8702682 | E10: =RC!E116 -> -6481970 | F10: =RC!F116 -> -6180455 | G10: =RC!G116 -> -6952573 | H10: =RC!H116 -> -6523415 | I10: =RC!I116 -> -6536916 | ... K10: =RC!K116 -> -5593293
A11: Acquisti con IVA gg | B11: =RC!B116*1.22/365 -> -30427.161 | C11: =RC!C116*1.22/365 -> -30024.638 | D11: =RC!D116*1.22/365 -> -29088.417 | E11: =RC!E116*1.22/365 -> -21665.763 | F11: =RC!F116*1.22/365 -> -20657.959 | G11: =RC!G116*1.22/365 -> -23238.737 | H11: =RC!H116*1.22/365 -> -21804.291 | I11: =RC!I116*1.22/365 -> -21849.418 | ... K11: =RC!K116*1.22/365 -> -18695.39
A12: Costo del venduto gg medio | B12: =AVERAGE(RC!B120:C120)/365 -> -24961.249 | C12: =AVERAGE(RC!C120:D120)/365 -> -23479.788 | D12: =AVERAGE(RC!D120:E120)/365 -> -20402.852 | E12: =AVERAGE(RC!E120:F120)/365 -> -17607.208 | F12: =AVERAGE(RC!F120:G120)/365 -> -18117.84 | G12: =AVERAGE(RC!G120:H120)/365 -> -18460.058 | H12: =AVERAGE(RC!H120:I120)/365 -> -17787.09 | I12: =AVERAGE(RC!I120:J120)/365 -> -17629.348 | ... K12: =AVERAGE(RC!K120:L120)/365 -> -14652.249
A13: Costo del personale gg medio | B13: =AVERAGE(RC!B122:C122)/365 -> -2957.2904 | C13: =AVERAGE(RC!C122:D122)/365 -> -2976.5712 | D13: =AVERAGE(RC!D122:E122)/365 -> -2734.1932 | E13: =AVERAGE(RC!E122:F122)/365 -> -2430.0753 | F13: =AVERAGE(RC!F122:G122)/365 -> -2436.7233 | G13: =AVERAGE(RC!G122:H122)/365 -> -2475.5192 | H13: =AVERAGE(RC!H122:I122)/365 -> -2249.7151 | I13: =AVERAGE(RC!I122:J122)/365 -> -1997.2849 | ... K13: =AVERAGE(RC!K122:L122)/365 -> -2086.5397
A14: AON* medio | B14: =AVERAGE(RC!B93,RC!C93) -> 4915610.5 | C14: =AVERAGE(RC!C93,RC!D93) -> 4968956 | D14: =AVERAGE(RC!D93,RC!E93) -> 4636713 | E14: =AVERAGE(RC!E93,RC!F93) -> 4707839 | F14: =AVERAGE(RC!F93,RC!G93) -> 4200158.5 | G14: =AVERAGE(RC!G93,RC!H93) -> 3534802.5 | H14: =AVERAGE(RC!H93,RC!I93) -> 3478864.5 | I14: =AVERAGE(RC!I93,RC!J93) -> 2942468.5 | ... K14: =AVERAGE(RC!K93,RC!L93) -> 3201983
A15: AON* init | B15: =RC!C93 -> 5156084 | C15: =RC!D93 -> 4781828 | D15: =RC!E93 -> 4491598 | E15: =RC!F93 -> 4924080 | F15: =RC!G93 -> 3476237 | G15: =RC!H93 -> 3593368 | H15: =RC!I93 -> 3364361 | I15: =RC!J93 -> 2520576 | ... K15: =RC!L93 -> 0
A16: AON* fin | B16: =RC!B93 -> 4675137 | C16: =RC!C93 -> 5156084 | D16: =RC!D93 -> 4781828 | E16: =RC!E93 -> 4491598 | F16: =RC!F93 -> 4924080 | G16: =RC!G93 -> 3476237 | H16: =RC!H93 -> 3593368 | I16: =RC!I93 -> 3364361 | ... K16: =RC!K93 -> 3201983
A17: Reddito att.acc (prov-oneri acc) | B17: =RC!B144 -> 0 | C17: =RC!C144 -> 0 | D17: =RC!D144 -> 0 | E17: =RC!E144 -> 0 | F17: =RC!F144 -> 0 | G17: =RC!G144 -> 0 | H17: =RC!H144 -> 0 | I17: =RC!I144 -> 0 | ... K17: =RC!K144 -> 0
A18: AACCN media(ris gest acc) | B18: =AVERAGE(RC!B94,RC!C94) -> 64500 | C18: =AVERAGE(RC!C94,RC!D94) -> 44500 | D18: =AVERAGE(RC!D94,RC!E94) -> 32000 | E18: =AVERAGE(RC!E94,RC!F94) -> 32000 | F18: =AVERAGE(RC!F94,RC!G94) -> 32000 | G18: =AVERAGE(RC!G94,RC!H94) -> 17000 | H18: =AVERAGE(RC!H94,RC!I94) -> 2000 | I18: =AVERAGE(RC!I94,RC!J94) -> 2000 | ... K18: =AVERAGE(RC!K94,RC!L94) -> 2000
A19: AACC medie(solo attività) | B19: =AVERAGE(RC!B27,RC!C27) -> 64500 | C19: =AVERAGE(RC!C27,RC!D27) -> 44500 | D19: =AVERAGE(RC!D27,RC!E27) -> 32000 | E19: =AVERAGE(RC!E27,RC!F27) -> 32000 | F19: =AVERAGE(RC!F27,RC!G27) -> 32000 | G19: =AVERAGE(RC!G27,RC!H27) -> 17000 | H19: =AVERAGE(RC!H27,RC!I27) -> 2000 | I19: =AVERAGE(RC!I27,RC!J27) -> 2000 | ... K19: =AVERAGE(RC!K27,RC!L27) -> 2000
A20: AACC finali | B20: =RC!B27 -> 72000 | C20: =RC!C27 -> 57000 | D20: =RC!D27 -> 32000 | E20: =RC!E27 -> 32000 | F20: =RC!F27 -> 32000 | G20: =RC!G27 -> 32000 | H20: =RC!H27 -> 2000 | I20: =RC!I27 -> 2000 | ... K20: =RC!K27 -> 2000
A21: PACC medie (solo passivo) | B21: =AVERAGE(RC!B66,RC!C66) -> 0 | C21: =AVERAGE(RC!C66,RC!D66) -> 0 | D21: =AVERAGE(RC!D66,RC!E66) -> 0 | E21: =AVERAGE(RC!E66,RC!F66) -> 0 | F21: =AVERAGE(RC!F66,RC!G66) -> 0 | G21: =AVERAGE(RC!G66,RC!H66) -> 0 | H21: =AVERAGE(RC!H66,RC!I66) -> 0 | I21: =AVERAGE(RC!I66,RC!J66) -> 0 | ... K21: =AVERAGE(RC!K66,RC!L66) -> 0
A22: PACC finali (solo passivo) | B22: =RC!B66 -> 0 | C22: =RC!C66 -> 0 | D22: =RC!D66 -> 0 | E22: =RC!E66 -> 0 | F22: =RC!F66 -> 0 | G22: =RC!G66 -> 0 | H22: =RC!H66 -> 0 | I22: =RC!I66 -> 0 | ... K22: =RC!K66 -> 0
A23: ris gest str | B23: =RC!B145 -> 0 | C23: =RC!C145 -> 0 | D23: =RC!D145 -> 0 | E23: =RC!E145 -> 0 | F23: =RC!F145 -> 0 | G23: =RC!G145 -> 0 | H23: =RC!H145 -> 0 | I23: =RC!I145 -> 0 | ... K23: =RC!K145 -> 0
A24: PFN (ris gest fin) | B24: =B30-B31 -> 1608403 | C24: =C30-C31 -> 1677525 | D24: =D30-D31 -> 1413573.5 | E24: =E30-E31 -> 1599175 | F24: =F30-F31 -> 2071482 | G24: =G30-G31 -> 2346407.5 | H24: =H30-H31 -> 2327583.5 | I24: =I30-I31 -> 2370843 | ... K24: =K30-K31 -> 2203518
A25: DEBn | B25: =IF(B24>0, B24, 0) -> 1608403 | C25: =IF(C24>0, C24, 0) -> 1677525 | D25: =IF(D24>0, D24, 0) -> 1413573.5 | E25: =IF(E24>0, E24, 0) -> 1599175 | F25: =IF(F24>0, F24, 0) -> 2071482 | G25: =IF(G24>0, G24, 0) -> 2346407.5 | H25: =IF(H24>0, H24, 0) -> 2327583.5 | I25: =IF(I24>0, I24, 0) -> 2370843 | ... K25: =IF(K24>0, K24, 0) -> 2203518
A26: LIQn | B26: =IF(B24<0, -B24, 0) -> 0 | C26: =IF(C24<0, C24, 0) -> 0 | D26: =IF(D24<0, D24, 0) -> 0 | E26: =IF(E24<0, E24, 0) -> 0 | F26: =IF(F24<0, F24, 0) -> 0 | G26: =IF(G24<0, G24, 0) -> 0 | H26: =IF(H24<0, H24, 0) -> 0 | I26: =IF(I24<0, I24, 0) -> 0 | J26: =IF(J24<0, J24, 0) -> 0 | K26: =IF(K24<0, K24, 0) -> 0
A27: oneri finanziari | B27: =RC!B138 -> -110269 | C27: =RC!C138 -> -101600 | D27: =RC!D138 -> -34715 | E27: =RC!E138 -> -32939 | F27: =RC!F138 -> -42003 | G27: =RC!G138 -> -43669 | H27: =RC!H138 -> -40987 | I27: =RC!I138 -> -52706 | ... K27: =RC!K138 -> -60976
A28: interessi attivi | B28: =RC!B137 -> 1525 | C28: =RC!C137 -> 2140 | D28: =RC!D137 -> 2565 | E28: =RC!E137 -> 4889 | F28: =RC!F137 -> 3414 | G28: =RC!G137 -> 4000 | H28: =RC!H137 -> 2187 | I28: =RC!I137 -> 2911 | ... K28: =RC!K137 -> 12
A29: imposta | B29: =RC!B149 -> -52061 | C29: =RC!C149 -> -34196 | D29: =RC!D149 -> -66907 | E29: =RC!E149 -> -39917 | F29: =RC!F149 -> -13565 | G29: =RC!G149 -> -20189 | H29: =RC!H149 -> -27527 | I29: =RC!I149 -> -12435 | ... K29: =RC!K149 -> -164164
A30: Debito lordo medio(pass. gest. fin) | B30: =AVERAGE(RC!B73,RC!C73) -> 1754991 | C30: =AVERAGE(RC!C73,RC!D73) -> 1781020 | D30: =AVERAGE(RC!D73,RC!E73) -> 1631841.5 | E30: =AVERAGE(RC!E73,RC!F73) -> 1973522 | F30: =AVERAGE(RC!F73,RC!G73) -> 2291459.5 | G30: =AVERAGE(RC!G73,RC!H73) -> 2387526.5 | H30: =AVERAGE(RC!H73,RC!I73) -> 2401427.5 | I30: =AVERAGE(RC!I73,RC!J73) -> 2425113.5 | ... K30: =AVERAGE(RC!K73,RC!L73) -> 2203518
A31: Liq. lorda media(att. gest fin) | B31: =AVERAGE(RC!B33,RC!C33) -> 146588 | C31: =AVERAGE(RC!C33,RC!D33) -> 103495 | D31: =AVERAGE(RC!D33,RC!E33) -> 218268 | E31: =AVERAGE(RC!E33,RC!F33) -> 374347 | F31: =AVERAGE(RC!F33,RC!G33) -> 219977.5 | G31: =AVERAGE(RC!G33,RC!H33) -> 41119 | H31: =AVERAGE(RC!H33,RC!I33) -> 73844 | I31: =AVERAGE(RC!I33,RC!J33) -> 54270.5 | ... K31: =AVERAGE(RC!K33,RC!L33) -> 0
A32: Crediti commerciali medi | B32: =AVERAGE(RC!B5:C5) -> 1364807.5 | C32: =AVERAGE(RC!C5:D5) -> 1326245 | D32: =AVERAGE(RC!D5:E5) -> 1182449 | E32: =AVERAGE(RC!E5:F5) -> 871810.5 | F32: =AVERAGE(RC!F5:G5) -> 892609 | G32: =AVERAGE(RC!G5:H5) -> 1038561 | H32: =AVERAGE(RC!H5:I5) -> 910853 | I32: =AVERAGE(RC!I5:J5) -> 807385 | ... K32: =AVERAGE(RC!K5:L5) -> 795525
A33: Debiti commerciali medi | B33: =AVERAGE(RC!B48,RC!C48) -> 1012072.5 | C33: =AVERAGE(RC!C48,RC!D48) -> 1047930.5 | D33: =AVERAGE(RC!D48,RC!E48) -> 946133.5 | E33: =AVERAGE(RC!E48,RC!F48) -> 639978 | F33: =AVERAGE(RC!F48,RC!G48) -> 539441.5 | G33: =AVERAGE(RC!G48,RC!H48) -> 588493.5 | H33: =AVERAGE(RC!H48,RC!I48) -> 615389 | I33: =AVERAGE(RC!I48,RC!J48) -> 625322 | ... K33: =AVERAGE(RC!K48,RC!L48) -> 622035
A34: Rimanenze magazzino medie | B34: =AVERAGE(RC!B6,RC!C6) -> 1257418.5 | C34: =AVERAGE(RC!C6,RC!D6) -> 1325280 | D34: =AVERAGE(RC!D6,RC!E6) -> 1052671.5 | E34: =AVERAGE(RC!E6,RC!F6) -> 907386.5 | F34: =AVERAGE(RC!F6,RC!G6) -> 1002805 | G34: =AVERAGE(RC!G6,RC!H6) -> 1049302.5 | H34: =AVERAGE(RC!H6,RC!I6) -> 1049229 | I34: =AVERAGE(RC!I6,RC!J6) -> 498364 | ... K34: =AVERAGE(RC!K6,RC!L6) -> 986831
A35: Rimanenze magazzino finali | B35: =RC!B6 -> 1163582 | C35: =RC!C6 -> 1351255 | D35: =RC!D6 -> 1299305 | E35: =RC!E6 -> 806038 | F35: =RC!F6 -> 1008735 | G35: =RC!G6 -> 996875 | H35: =RC!H6 -> 1101730 | I35: =RC!I6 -> 996728 | ... K35: =RC!K6 -> 986831
A36: Attività a BT | B36: =AVERAGE(RC!B8:C8)+AVERAGE(RC!B19:C19)+AVERAGE(RC!B30:C30) -> 2749317.5 | C36: =AVERAGE(RC!C8:D8)+AVERAGE(RC!C19:D19)+AVERAGE(RC!C30:D30) -> 2829118.5 | D36: =AVERAGE(RC!D8:E8)+AVERAGE(RC!D19:E19)+AVERAGE(RC!D30:E30) -> 2375333.5 | E36: =AVERAGE(RC!E8:F8)+AVERAGE(RC!E19:F19)+AVERAGE(RC!E30:F30) -> 1917385.5 | F36: =AVERAGE(RC!F8:G8)+AVERAGE(RC!F19:G19)+AVERAGE(RC!F30:G30) -> 2036517.5 | G36: =AVERAGE(RC!G8:H8)+AVERAGE(RC!G19:H19)+AVERAGE(RC!G30:H30) -> 2231275.5 | H36: =AVERAGE(RC!H8:I8)+AVERAGE(RC!H19:I19)+AVERAGE(RC!H30:I30) -> 2129390.5 | I36: =AVERAGE(RC!I8:J8)+AVERAGE(RC!I19:J19)+AVERAGE(RC!I30:J30) -> 1494554.5 | ... K36: =AVERAGE(RC!K8:L8)+AVERAGE(RC!K19:L19)+AVERAGE(RC!K30:L30) -> 2012254
A37: Attività a BT finali | B37: =RC!B8+RC!B19+RC!B30 -> 2569788 | C37: =RC!C8+RC!C19+RC!C30 -> 2928847 | D37: =RC!D8+RC!D19+RC!D30 -> 2729390 | E37: =RC!E8+RC!E19+RC!E30 -> 2021277 | F37: =RC!F8+RC!F19+RC!F30 -> 1813494 | G37: =RC!G8+RC!G19+RC!G30 -> 2259541 | H37: =RC!H8+RC!H19+RC!H30 -> 2203010 | I37: =RC!I8+RC!I19+RC!I30 -> 2055771 | ... K37: =RC!K8+RC!K19+RC!K30 -> 2012254
A38: Passività a BT medie | B38: =AVERAGE(RC!B51:C51)+AVERAGE(RC!B59:C59)+AVERAGE(RC!B70:C70) -> 2127108.5 | C38: =AVERAGE(RC!C51:D51)+AVERAGE(RC!C59:D59)+AVERAGE(RC!C70:D70) -> 1933434.5 | D38: =AVERAGE(RC!D51:E51)+AVERAGE(RC!D59:E59)+AVERAGE(RC!D70:E70) -> 1518948.5 | E38: =AVERAGE(RC!E51:F51)+AVERAGE(RC!E59:F59)+AVERAGE(RC!E70:F70) -> 1298891 | F38: =AVERAGE(RC!F51:G51)+AVERAGE(RC!F59:G59)+AVERAGE(RC!F70:G70) -> 1804966.5 | G38: =AVERAGE(RC!G51:H51)+AVERAGE(RC!G59:H59)+AVERAGE(RC!G70:H70) -> 2295620 | H38: =AVERAGE(RC!H51:I51)+AVERAGE(RC!H59:I59)+AVERAGE(RC!H70:I70) -> 2113880.5 | I38: =AVERAGE(RC!I51:J51)+AVERAGE(RC!I59:J59)+AVERAGE(RC!I70:J70) -> 1937224.5 | ... K38: =AVERAGE(RC!K51:L51)+AVERAGE(RC!K59:L59)+AVERAGE(RC!K70:L70) -> 1592282
A39: Passività a BT finali | B39: =RC!B51+RC!B59+RC!B70 -> 2059586 | C39: =RC!C51+RC!C59+RC!C70 -> 2194631 | D39: =RC!D51+RC!D59+RC!D70 -> 1672238 | E39: =RC!E51+RC!E59+RC!E70 -> 1365659 | F39: =RC!F51+RC!F59+RC!F70 -> 1232123 | G39: =RC!G51+RC!G59+RC!G70 -> 2377810 | H39: =RC!H51+RC!H59+RC!H70 -> 2213430 | I39: =RC!I51+RC!I59+RC!I70 -> 2014331 | ... K39: =RC!K51+RC!K59+RC!K70 -> 1592282
A40: Passività operative consolidate medie | B40: =AVERAGE(RC!B52,RC!C52) -> 0 | C40: =AVERAGE(RC!C52,RC!D52) -> 0 | D40: =AVERAGE(RC!D52,RC!E52) -> 0 | E40: =AVERAGE(RC!E52,RC!F52) -> 0 | F40: =AVERAGE(RC!F52,RC!G52) -> 0 | G40: =AVERAGE(RC!G52,RC!H52) -> 0 | H40: =AVERAGE(RC!H52,RC!I52) -> 0 | I40: =AVERAGE(RC!I52,RC!J52) -> 0 | ... K40: =AVERAGE(RC!K52,RC!L52) -> 0
...

Sheet grph
B3: Quozienti di redditività
B80: Quozienti di rotazione dell'attivo netto
B135: Quozienti di liquidità ed equilibrio fonti/impieghi
B218: Indicatori di robustezza
