Workbook

Sheet input
A1: Anno | B1: 31/12/2024 | C1: 31/12/2023 | D1: 31/12/2022 | E1: 31/12/2021 | F1: 31/12/2020 | G1: 31/12/2019 | H1: 31/12/2018 | I1: 31/12/2017 | J1: 31/12/2016 | K1: 31/12/2015
A2: A. CREDITI VERSO SOCI | B2: 0 | C2: 0 | D2: 0 | E2: 0 | F2: 0 | G2: 0 | H2: 0 | I2: 0 | J2: 0 | K2: 0
A3: Quota di capitale richiamata | B3: 0 | C3: 0 | D3: 0 | E3: 0 | F3: 0 | G3: 0 | H3: 0 | I3: 0 | J3: 0 | K3: 0
A4: B. TOTALE IMMOBILIZZAZIONI sep.ind. Di quelle conc. In loc. Finanz. | B4: 2855833 | C4: 870568 | D4: 1067260.9 | E4: 891346.47 | F4: 906632.62 | G4: 378046.95 | H4: 394745.36 | I4: 421605.02 | J4: 421402.53 | K4: 422213.42
A5: B.I. TOTALE IMMOB. IMMATERIALI | B5: 1592262 | C5: 90098 | D5: 86779.886 | E5: 89055.322 | F5: 87656.701 | G5: 13306.33 | H5: 11674.413 | I5: 12394.555 | J5: 14257.563 | K5: 16231.349
A6: B.I.1. Costi impianto e ampl. | B6: 0 | C6: 0 | D6: 0 | E6: 0 | F6: 0 | G6: 0 | H6: 0 | I6: 0 | J6: 0 | K6: 0
A7: B.I.2. Costi ricerca e pubb. | B7: 0 | C7: 0 | D7: 770.608 | E7: 1105.122 | F7: 0 | G7: 0 | H7: 0 | I7: 0 | J7: 0 | K7: 0
A8: B.I.3. Diritti brevetto ind. | B8: 0 | C8: 0 | D8: 12189.851 | E8: 11548.739 | F8: 4441.959 | G8: 4819.24 | H8: 1058.732 | I8: 1177.061 | J8: 1355.297 | K8: 1568.018
A9: B.I.4. Concessioni, licenze | B9: 0 | C9: 0 | D9: 37175.784 | E9: 39674.967 | F9: 42112.582 | G9: 8248.91 | H9: 9568.06 | I9: 11008.448 | J9: 12605.625 | K9: 14213.551
A10: B.I.5. Avviamento/Differenza di consolidamento | B10: 0 | C10: 0 | D10: 29953.918 | E10: 31715.913 | F10: 33477.908 | G10: 0 | H10: 0 | I10: 0 | J10: 0 | K10: 14.688
A11: di cui: Avviamento | B11: 0 | C11: 0 | D11: 29953.918 | E11: 31715.913 | F11: 33477.908 | G11: 0 | H11: 0 | I11: 0 | J11: 0 | K11: 14.688
A12: B.I.6. Imm. in corso | B12: 0 | C12: 0 | D12: 4575.518 | E12: 2874.101 | F12: 5851.812 | G12: 116.543 | H12: 884.224 | I12: 0 | J12: 0 | K12: 0
A13: B.I.7. Altre immobiliz. Immateriali | B13: 1592262 | C13: 90098 | D13: 2114.207 | E13: 2136.48 | F13: 1772.44 | G13: 121.637 | H13: 163.397 | I13: 209.046 | J13: 296.641 | K13: 435.092
... A93: TOTALE ATTIVO | B93: 3790320 | C93: 1675063 | D93: 1536537 | E93: 1308756.7 | F93: 1311132.3 | G93: 741974.82 | H93: 792683.74 | I93: 788836.85 | J93: 778185.57 | K93: 780383.29
A94: Passivo
A95: PATRIMONIO NETTO
A96: A. TOTALE PATRIMONIO NETTO | B96: 852247 | C96: 88219 | D96: 136548.72 | E96: 117108.52 | F96: 124862.24 | G96: 344954.71 | H96: 348518.46 | I96: 370611.09 | J96: 351645.83 | K96: 318992.28
A97: A.I. Capitale sociale | B97: 40000 | C97: 40000 | D97: 40000.22 | E97: 40000.22 | F97: 40000.22 | G97: 40000.22 | H97: 40000.22 | I97: 40000.22 | J97: 40000.22 | K97: 40000.22
A98: di cui: Versamenti soci in c/capitale | B98: 0 | C98: 0 | D98: 4500 | E98: 0 | F98: 0 | G98: 0.098 | H98: 0.098 | I98: 0.098 | J98: 0.098 | K98: 0.098
A99: di cui: Versamenti in c/futuro aumento di capitale | B99: 0 | C99: 0 | D99: 0 | E99: 0 | F99: 0 | G99: 0 | H99: 0 | I99: 0 | J99: 0 | K99: 0
A100: di cui: Versamenti in c/capitale | B100: 0 | C100: 0 | D100: 0 | E100: 0 | F100: 0 | G100: 0 | H100: 0 | I100: 0 | J100: 0 | K100: 0
A101: di cui: Versamenti a copertura perdite | B101: 0 | C101: 0 | D101: 0 | E101: 0 | F101: 0 | G101: 0 | H101: 0 | I101: 0 | J101: 0 | K101: 0
A102: A.II. Riserva da sovrapprezzo | B102: 60241 | C102: 60241 | D102: 60241.454 | E102: 60241.454 | F102: 60241.454 | G102: 51829.138 | H102: 51829.138 | I102: 51829.138 | J102: 51829.138 | K102: 51829.138
A103: A.III. Riserva di rivalutazione | B103: 0 | C103: 0 | D103: 15471.903 | E103: 15471.903 | F103: 15471.903 | G103: 15471.903 | H103: 15471.903 | I103: 15471.903 | J103: 15471.903 | K103: 15471.903
A104: A.IV. Riserva legale | B104: 8000 | C104: 8000 | D104: 8000.044 | E104: 8000.044 | F104: 8000.044 | G104: 8000.044 | H104: 8000.044 | I104: 8000.044 | J104: 8000.044 | K104: 8000.044
A105: A.V. Riserva statutaria | B105: 0 | C105: 0 | D105: 0 | E105: 0 | F105: 0 | G105: 0 | H105: 0 | I105: 0 | J105: 0 | K105: 0
A106: Riserva azioni proprie | B106: 0 | C106: 0 | D106: 0 | E106: 0 | F106: 0 | G106: 0 | H106: 0 | I106: 0 | J106: 0 | K106: 0
A107: A.VI. Altre riserve | B107: 1178691 | C107: 96414 | D107: 62110.595 | E107: 57610.595 | F107: 57610.595 | G107: 229217.16 | H107: 227309.63 | I107: 206344.36 | J107: 181690.86 | K107: 164816.55
... A126: C. TRATTAMENTO DI FINE RAPPORTO | B126: 6126 | C126: 7190 | D126: 9844.145 | E126: 9804.363 | F126: 11127.204 | G126: 13315.664 | H126: 14615.308 | I126: 15818.5 | J126: 16934.442 | K126: 17851.924
A127: Debiti
A128: D. TOTALE DEBITI | B128: 2796886 | C128: 1522481 | D128: 1327820.1 | E128: 1136860.7 | F128: 1126282.8 | G128: 348491.19 | H128: 397384.07 | I128: 375606.9 | J128: 392361.16 | K128: 433764.15
A129: D.1. Obblig.ni entro | B129: 6783 | C129: 0 | D129: 0 | E129: 0 | F129: 0 | G129: 0 | H129: 0 | I129: 0 | J129: 0 | K129: 0
A130: D.1. Obblig.ni oltre | B130: 1069074 | C130: 0 | D130: 0 | E130: 0 | F130: 0 | G130: 0 | H130: 0 | I130: 0 | J130: 0 | K130: 0
A131: D.2. Obblig.ni convert. entro | B131: 0 | C131: 0 | D131: 0 | E131: 0 | F131: 0 | G131: 0 | H131: 0 | I131: 0 | J131: 0 | K131: 0
A132: D.2. Obblig.ni convert. oltre. | B132: 0 | C132: 0 | D132: 0 | E132: 0 | F132: 0 | G132: 0 | H132: 0 | I132: 0 | J132: 0 | K132: 0
A133: D.3. Soci per Finanziamenti entro | B133: 0 | C133: 0 | D133: 0 | E133: 0 | F133: 0 | G133: 0 | H133: 0 | I133: 0 | J133: 0 | K133: 0
A134: D.3. Soci per Finanziamenti oltre | B134: 322056 | C134: 0 | D134: 0 | E134: 0 | F134: 0 | G134: 0 | H134: 0 | I134: 0 | J134: 0 | K134: 0
A135: D.4. Banche entro l'esercizio | B135: 82489 | C135: 48202 | D135: 10000 | E135: 0.499 | F135: 1.807 | G135: 4.922 | H135: 20464.468 | I135: 99547.086 | J135: 79477.82 | K135: 100222.99
A136: D.4. Banche oltre l'esercizio | B136: 178111 | C136: 614866 | D136: 0 | E136: 0 | F136: 0 | G136: 0 | H136: 0 | I136: 55779.956 | J136: 79869.756 | K136: 103275.9
A137: D.5. Altri finanziatori entro | B137: 17028 | C137: 14288 | D137: 15075.841 | E137: 12408.767 | F137: 18709.528 | G137: 0 | H137: 0 | I137: 428.265 | J137: 0 | K137: 282.108
...

Sheet case
A1: SP attivo | B1: =input!B1 -> 31/12/2024 | C1: =input!C1 -> 31/12/2023 | D1: =input!D1 -> 31/12/2022 | E1: =input!E1 -> 31/12/2021 | F1: =input!F1 -> 31/12/2020 | G1: =input!G1 -> 31/12/2019 | H1: =input!H1 -> 31/12/2018 | I1: =input!I1 -> 31/12/2017 | ... K1: =input!K1 -> 31/12/2015 | M1: Segno | N1: Riclassificazione
A2: =input!A2 -> A. CREDITI VERSO SOCI | B2: =$M2*input!B2 -> 0 | C2: =$M2*input!C2 -> 0 | D2: =$M2*input!D2 -> 0 | E2: =$M2*input!E2 -> 0 | F2: =$M2*input!F2 -> 0 | G2: =$M2*input!G2 -> 0 | H2: =$M2*input!H2 -> 0 | I2: =$M2*input!I2 -> 0 | ... K2: =$M2*input!K2 -> 0 | M2: -1 | N2: Finanziamenti netti vs soci e controllanti
A3: =input!A3 -> Quota di capitale richiamata | B3: =$M3*input!B3 -> 0 | C3: =$M3*input!C3 -> 0 | D3: =$M3*input!D3 -> 0 | E3: =$M3*input!E3 -> 0 | F3: =$M3*input!F3 -> 0 | G3: =$M3*input!G3 -> 0 | H3: =$M3*input!H3 -> 0 | I3: =$M3*input!I3 -> 0 | ... K3: =$M3*input!K3 -> 0 | M3: 1
A5: =input!A4 -> B. TOTALE IMMOBILIZZAZIONI sep.ind. Di quelle conc. In loc. Finanz. | B5: =$M5*input!B4 -> 2855833 | C5: =$M5*input!C4 -> 870568 | D5: =$M5*input!D4 -> 1067260.9 | E5: =$M5*input!E4 -> 891346.47 | F5: =$M5*input!F4 -> 906632.62 | G5: =$M5*input!G4 -> 378046.95 | H5: =$M5*input!H4 -> 394745.36 | I5: =$M5*input!I4 -> 421605.02 | ... K5: =$M5*input!K4 -> 422213.42 | M5: 1
A6: =input!A5 -> B.I. TOTALE IMMOB. IMMATERIALI | B6: =$M6*input!B5 -> 1592262 | C6: =$M6*input!C5 -> 90098 | D6: =$M6*input!D5 -> 86779.886 | E6: =$M6*input!E5 -> 89055.322 | F6: =$M6*input!F5 -> 87656.701 | G6: =$M6*input!G5 -> 13306.33 | H6: =$M6*input!H5 -> 11674.413 | I6: =$M6*input!I5 -> 12394.555 | ... K6: =$M6*input!K5 -> 16231.349 | M6: 1 | N6: Immobilizzazioni immateriali nette
A7: =input!A6 -> B.I.1. Costi impianto e ampl. | B7: =$M7*input!B6 -> 0 | C7: =$M7*input!C6 -> 0 | D7: =$M7*input!D6 -> 0 | E7: =$M7*input!E6 -> 0 | F7: =$M7*input!F6 -> 0 | G7: =$M7*input!G6 -> 0 | H7: =$M7*input!H6 -> 0 | I7: =$M7*input!I6 -> 0 | ... K7: =$M7*input!K6 -> 0 | M7: 1
A8: =input!A7 -> B.I.2. Costi ricerca e pubb. | B8: =$M8*input!B7 -> 0 | C8: =$M8*input!C7 -> 0 | D8: =$M8*input!D7 -> 770.608 | E8: =$M8*input!E7 -> 1105.122 | F8: =$M8*input!F7 -> 0 | G8: =$M8*input!G7 -> 0 | H8: =$M8*input!H7 -> 0 | I8: =$M8*input!I7 -> 0 | ... K8: =$M8*input!K7 -> 0 | M8: 1
A9: =input!A8 -> B.I.3. Diritti brevetto ind. | B9: =$M9*input!B8 -> 0 | C9: =$M9*input!C8 -> 0 | D9: =$M9*input!D8 -> 12189.851 | E9: =$M9*input!E8 -> 11548.739 | F9: =$M9*input!F8 -> 4441.959 | G9: =$M9*input!G8 -> 4819.24 | H9: =$M9*input!H8 -> 1058.732 | I9: =$M9*input!I8 -> 1177.061 | ... K9: =$M9*input!K8 -> 1568.018 | M9: 1
A10: =input!A9 -> B.I.4. Concessioni, licenze | B10: =$M10*input!B9 -> 0 | C10: =$M10*input!C9 -> 0 | D10: =$M10*input!D9 -> 37175.784 | E10: =$M10*input!E9 -> 39674.967 | F10: =$M10*input!F9 -> 42112.582 | G10: =$M10*input!G9 -> 8248.91 | H10: =$M10*input!H9 -> 9568.06 | I10: =$M10*input!I9 -> 11008.448 | ... K10: =$M10*input!K9 -> 14213.551 | M10: 1
A11: =input!A10 -> B.I.5. Avviamento/Differenza di consolidamento | B11: =$M11*input!B10 -> 0 | C11: =$M11*input!C10 -> 0 | D11: =$M11*input!D10 -> 29953.918 | E11: =$M11*input!E10 -> 31715.913 | F11: =$M11*input!F10 -> 33477.908 | G11: =$M11*input!G10 -> 0 | H11: =$M11*input!H10 -> 0 | I11: =$M11*input!I10 -> 0 | ... K11: =$M11*input!K10 -> 14.688 | M11: 1
A12: =input!A11 -> di cui: Avviamento | B12: =$M12*input!B11 -> 0 | C12: =$M12*input!C11 -> 0 | D12: =$M12*input!D11 -> 29953.918 | E12: =$M12*input!E11 -> 31715.913 | F12: =$M12*input!F11 -> 33477.908 | G12: =$M12*input!G11 -> 0 | H12: =$M12*input!H11 -> 0 | I12: =$M12*input!I11 -> 0 | ... K12: =$M12*input!K11 -> 14.688 | M12: 1
A13: =input!A12 -> B.I.6. Imm. in corso | B13: =$M13*input!B12 -> 0 | C13: =$M13*input!C12 -> 0 | D13: =$M13*input!D12 -> 4575.518 | E13: =$M13*input!E12 -> 2874.101 | F13: =$M13*input!F12 -> 5851.812 | G13: =$M13*input!G12 -> 116.543 | H13: =$M13*input!H12 -> 884.224 | I13: =$M13*input!I12 -> 0 | ... K13: =$M13*input!K12 -> 0 | M13: 1
A14: =input!A13 -> B.I.7. Altre immobiliz. Immateriali | B14: =$M14*input!B13 -> 1592262 | C14: =$M14*input!C13 -> 90098 | D14: =$M14*input!D13 -> 2114.207 | E14: =$M14*input!E13 -> 2136.48 | F14: =$M14*input!F13 -> 1772.44 | G14: =$M14*input!G13 -> 121.637 | H14: =$M14*input!H13 -> 163.397 | I14: =$M14*input!I13 -> 209.046 | ... K14: =$M14*input!K13 -> 435.092 | M14: 1
A15: =input!A14 -> Fondo amm.to Immob. Immateriali | B15: =$M15*input!B14 -> 0 | C15: =$M15*input!C14 -> 0 | D15: =$M15*input!D14 -> 0 | E15: =$M15*input!E14 -> 0 | F15: =$M15*input!F14 -> 0 | G15: =$M15*input!G14 -> 0 | H15: =$M15*input!H14 -> 0 | I15: =$M15*input!I14 -> 0 | ... K15: =$M15*input!K14 -> 0 | M15: 1
A16: =input!A15 -> B.II. TOTALE IMMOB. MATERIALI | B16: =$M16*input!B15 -> 247743 | C16: =$M16*input!C15 -> 220617 | D16: =$M16*input!D15 -> 223741.13 | E16: =$M16*input!E15 -> 217974.81 | F16: =$M16*input!F15 -> 220394.5 | G16: =$M16*input!G15 -> 154055.72 | H16: =$M16*input!H15 -> 149620.66 | I16: =$M16*input!I15 -> 148980.38 | ... K16: =$M16*input!K15 -> 152948.57 | M16: 1 | N16: Immobilizzazioni materiali nette
A17: =input!A16 -> di cui: Beni materiali concessi in locazione finanziaria | B17: =$M17*input!B16 -> 0 | C17: =$M17*input!C16 -> 0 | D17: =$M17*input!D16 -> 0 | E17: =$M17*input!E16 -> 0 | F17: =$M17*input!F16 -> 0 | G17: =$M17*input!G16 -> 0 | H17: =$M17*input!H16 -> 0 | I17: =$M17*input!I16 -> 0 | ... K17: =$M17*input!K16 -> 0 | M17: 1
A18: =input!A17 -> B.II.1. Terreni e fabbricati | B18: =$M18*input!B17 -> 14339 | C18: =$M18*input!C17 -> 46689 | D18: =$M18*input!D17 -> 76679.059 | E18: =$M18*input!E17 -> 79327.474 | F18: =$M18*input!F17 -> 87475.546 | G18: =$M18*input!G17 -> 51009.244 | H18: =$M18*input!H17 -> 52883.326 | I18: =$M18*input!I17 -> 53993.851 | ... K18: =$M18*input!K17 -> 59775.425 | M18: 1
A19: =input!A18 -> B.II.2. Impianti | B19: =$M19*input!B18 -> 125344 | C19: =$M19*input!C18 -> 100960 | D19: =$M19*input!D18 -> 125560.36 | E19: =$M19*input!E18 -> 128183.84 | F19: =$M19*input!F18 -> 124380.4 | G19: =$M19*input!G18 -> 86311.778 | H19: =$M19*input!H18 -> 88171.71 | I19: =$M19*input!I18 -> 82537.405 | ... K19: =$M19*input!K18 -> 89532.66 | M19: 1
A20: =input!A19 -> B.II.3. Attrez. industriali | B20: =$M20*input!B19 -> 249 | C20: =$M20*input!C19 -> 315 | D20: =$M20*input!D19 -> 458.76 | E20: =$M20*input!E19 -> 498 | F20: =$M20*input!F19 -> 434.511 | G20: =$M20*input!G19 -> 430.921 | H20: =$M20*input!H19 -> 503.653 | I20: =$M20*input!I19 -> 633.098 | ... K20: =$M20*input!K19 -> 906.995 | M20: 1
A21: =input!A20 -> B.II.4. Altri beni | B21: =$M21*input!B20 -> 91805 | C21: =$M21*input!C20 -> 58021 | D21: =$M21*input!D20 -> 489.163 | E21: =$M21*input!E20 -> 441.528 | F21: =$M21*input!F20 -> 511.287 | G21: =$M21*input!G20 -> 603.536 | H21: =$M21*input!H20 -> 653.076 | I21: =$M21*input!I20 -> 735.094 | ... K21: =$M21*input!K20 -> 906.335 | M21: 1
A22: =input!A21 -> B.II.5. Imm. in corso/acconti | B22: =$M22*input!B21 -> 16006 | C22: =$M22*input!C21 -> 14632 | D22: =$M22*input!D21 -> 20553.787 | E22: =$M22*input!E21 -> 9523.963 | F22: =$M22*input!F21 -> 7592.753 | G22: =$M22*input!G21 -> 15700.24 | H22: =$M22*input!H21 -> 7408.897 | I22: =$M22*input!I21 -> 11080.927 | ... K22: =$M22*input!K21 -> 1827.151 | M22: 1
A23: =input!A22 -> Fondo amm.to Immob. Materiali | B23: =$M23*input!B22 -> 0 | C23: =$M23*input!C22 -> 0 | D23: =$M23*input!D22 -> 0 | E23: =$M23*input!E22 -> 0 | F23: =$M23*input!F22 -> 0 | G23: =$M23*input!G22 -> 0 | H23: =$M23*input!H22 -> 0 | I23: =$M23*input!I22 -> 0 | ... K23: =$M23*input!K22 -> 0 | M23: 1
A24: =input!A23 -> B.III. TOTALE IMMOB. FINANZIARIE | B24: =$M24*input!B23 -> 1015828 | C24: =$M24*input!C23 -> 559853 | D24: =$M24*input!D23 -> 756739.9 | E24: =$M24*input!E23 -> 584316.34 | F24: =$M24*input!F23 -> 598581.42 | G24: =$M24*input!G23 -> 210684.9 | H24: =$M24*input!H23 -> 233450.29 | I24: =$M24*input!I23 -> 260230.09 | ... K24: =$M24*input!K23 -> 253033.51 | M24: 1
A25: =input!A24 -> di cui: esigibili entro l'esercizio successivo | B25: =$M25*input!B24 -> 0 | C25: =$M25*input!C24 -> 0 | D25: =$M25*input!D24 -> 10782.128 | E25: =$M25*input!E24 -> 343.435 | F25: =$M25*input!F24 -> 370.685 | G25: =$M25*input!G24 -> 324.796 | H25: =$M25*input!H24 -> 281.976 | I25: =$M25*input!I24 -> 278.258 | ... K25: =$M25*input!K24 -> 286.84 | M25: 1
A26: =input!A25 -> B.III.1. TOT Partecipazioni | B26: =$M26*input!B25 -> 1015828 | C26: =$M26*input!C25 -> 559853 | D26: =$M26*input!D25 -> 556283.77 | E26: =$M26*input!E25 -> 484337.02 | F26: =$M26*input!F25 -> 436771.36 | G26: =$M26*input!G25 -> 185287.81 | H26: =$M26*input!H25 -> 205707.91 | I26: =$M26*input!I25 -> 232021.82 | ... K26: =$M26*input!K25 -> 248664.75 | M26: 1
A27: =input!A26 -> B.III.1.a. Imprese controllate | B27: =$M27*input!B26 -> 1012239 | C27: =$M27*input!C26 -> 557430 | D27: =$M27*input!D26 -> 555588.13 | E27: =$M27*input!E26 -> 483640.37 | F27: =$M27*input!F26 -> 436074.72 | G27: =$M27*input!G26 -> 184591.17 | H27: =$M27*input!H26 -> 205011.27 | I27: =$M27*input!I26 -> 231325.17 | ... K27: =$M27*input!K26 -> 247968.1 | M27: 1 | N27: Partecipazioni
A28: =input!A27 -> B.III.1.b. Imprese collegate | B28: =$M28*input!B27 -> 0 | C28: =$M28*input!C27 -> 0 | D28: =$M28*input!D27 -> 695.516 | E28: =$M28*input!E27 -> 695.516 | F28: =$M28*input!F27 -> 695.516 | G28: =$M28*input!G27 -> 695.516 | H28: =$M28*input!H27 -> 695.516 | I28: =$M28*input!I27 -> 695.516 | ... K28: =$M28*input!K27 -> 695.516 | M28: 1 | N28: Partecipazioni
A29: =input!A28 -> B.III.1.c. Imprese controllanti | B29: =$M29*input!B28 -> 0 | C29: =$M29*input!C28 -> 0 | D29: =$M29*input!D28 -> 0 | E29: =$M29*input!E28 -> 0 | F29: =$M29*input!F28 -> 0 | G29: =$M29*input!G28 -> 0 | H29: =$M29*input!H28 -> 0 | I29: =$M29*input!I28 -> 0 | ... K29: =$M29*input!K28 -> 0 | M29: 1 | N29: Azioni proprie e partecipazioni in controllanti
A30: =input!A29 -> B.III.1.d. In imprese sottoposte al controllo delle controllanti | B30: =$M30*input!B29 -> 0 | C30: =$M30*input!C29 -> 0 | D30: =$M30*input!D29 -> 0 | E30: =$M30*input!E29 -> 0 | F30: =$M30*input!F29 -> 0 | G30: =$M30*input!G29 -> 0 | H30: =$M30*input!H29 -> 0 | I30: =$M30*input!I29 -> 0 | ... K30: =$M30*input!K29 -> 0 | M30: 1 | N30: Azioni proprie e partecipazioni in controllanti
A31: =input!A30 -> B.III.1.d.bis. Altre imprese | B31: =$M31*input!B30 -> 3589 | C31: =$M31*input!C30 -> 2423 | D31: =$M31*input!D30 -> 0.129 | E31: =$M31*input!E30 -> 1.129 | F31: =$M31*input!F30 -> 1.129 | G31: =$M31*input!G30 -> 1.129 | H31: =$M31*input!H30 -> 1.129 | I31: =$M31*input!I30 -> 1.129 | ... K31: =$M31*input!K30 -> 1.129 | M31: 1 | N31: Partecipazioni
A32: =input!A31 -> B.III.2. TOT CREDITI Imm. Fin. | B32: =$M32*input!B31 -> 0 | C32: =$M32*input!C31 -> 0 | D32: =$M32*input!D31 -> 200456.12 | E32: =$M32*input!E31 -> 99979.325 | F32: =$M32*input!F31 -> 161810.06 | G32: =$M32*input!G31 -> 25397.088 | H32: =$M32*input!H31 -> 27742.372 | I32: =$M32*input!I31 -> 28208.271 | ... K32: =$M32*input!K31 -> 4368.757 | M32: 1
A33: =input!A32 -> B.III.2.a. Cred. vs Controllate entro | B33: =$M33*input!B32 -> 0 | C33: =$M33*input!C32 -> 0 | D33: =$M33*input!D32 -> 0 | E33: =$M33*input!E32 -> 0 | F33: =$M33*input!F32 -> 0 | G33: =$M33*input!G32 -> 0 | H33: =$M33*input!H32 -> 0 | I33: =$M33*input!I32 -> 0 | ... K33: =$M33*input!K32 -> 0 | M33: 1 | N33: Crediti vs controllate e collegate
A34: =input!A33 -> B.III.2.a. Cred. vs Controllate oltre | B34: =$M34*input!B33 -> 0 | C34: =$M34*input!C33 -> 0 | D34: =$M34*input!D33 -> 189673.99 | E34: =$M34*input!E33 -> 99635.89 | F34: =$M34*input!F33 -> 161439.38 | G34: =$M34*input!G33 -> 25072.292 | H34: =$M34*input!H33 -> 27460.396 | I34: =$M34*input!I33 -> 27930.013 | ... K34: =$M34*input!K33 -> 4081.917 | M34: 1 | N34: Crediti vs controllate e collegate
A35: =input!A34 -> B.III.2.b. Cred. vs Collegate entro | B35: =$M35*input!B34 -> 0 | C35: =$M35*input!C34 -> 0 | D35: =$M35*input!D34 -> 0 | E35: =$M35*input!E34 -> 0 | F35: =$M35*input!F34 -> 0 | G35: =$M35*input!G34 -> 0 | H35: =$M35*input!H34 -> 0 | I35: =$M35*input!I34 -> 0 | ... K35: =$M35*input!K34 -> 0 | M35: 1 | N35: Crediti vs controllate e collegate
A36: =input!A35 -> B.III.2.b. Cred. vs Collegate oltre | B36: =$M36*input!B35 -> 0 | C36: =$M36*input!C35 -> 0 | D36: =$M36*input!D35 -> 0 | E36: =$M36*input!E35 -> 0 | F36: =$M36*input!F35 -> 0 | G36: =$M36*input!G35 -> 0 | H36: =$M36*input!H35 -> 0 | I36: =$M36*input!I35 -> 0 | ... K36: =$M36*input!K35 -> 0 | M36: 1 | N36: Crediti vs controllate e collegate
A37: =input!A36 -> B.III.2.c. Cred. vs Controllanti entro | B37: =$M37*input!B36 -> 0 | C37: =$M37*input!C36 -> 0 | D37: =$M37*input!D36 -> 0 | E37: =$M37*input!E36 -> 0 | F37: =$M37*input!F36 -> 0 | G37: =$M37*input!G36 -> 0 | H37: =$M37*input!H36 -> 0 | I37: =$M37*input!I36 -> 0 | ... K37: =$M37*input!K36 -> 0 | M37: -1 | N37: Finanziamenti netti vs soci e controllanti
A38: =input!A37 -> B.III.2.c. Cred. vs Controllanti oltre | B38: =$M38*input!B37 -> 0 | C38: =$M38*input!C37 -> 0 | D38: =$M38*input!D37 -> 0 | E38: =$M38*input!E37 -> 0 | F38: =$M38*input!F37 -> 0 | G38: =$M38*input!G37 -> 0 | H38: =$M38*input!H37 -> 0 | I38: =$M38*input!I37 -> 0 | ... K38: =$M38*input!K37 -> 0 | M38: -1 | N38: Finanziamenti netti vs soci e controllanti
A39: =input!A38 -> B.III.2.d. Cred. vs imprese sottoposte al controllo delle controllanti entro | B39: =$M39*input!B38 -> 0 | C39: =$M39*input!C38 -> 0 | D39: =$M39*input!D38 -> 0 | E39: =$M39*input!E38 -> 0 | F39: =$M39*input!F38 -> 0 | G39: =$M39*input!G38 -> 0 | H39: =$M39*input!H38 -> 0 | I39: =$M39*input!I38 -> 0 | ... K39: =$M39*input!K38 -> 0 | M39: -1 | N39: Finanziamenti netti vs soci e controllanti
A40: =input!A39 -> B.III.2.d. Cred. vs imprese sottoposte al controllo delle controllanti oltre | B40: =$M40*input!B39 -> 0 | C40: =$M40*input!C39 -> 0 | D40: =$M40*input!D39 -> 0 | E40: =$M40*input!E39 -> 0 | F40: =$M40*input!F39 -> 0 | G40: =$M40*input!G39 -> 0 | H40: =$M40*input!H39 -> 0 | I40: =$M40*input!I39 -> 0 | ... K40: =$M40*input!K39 -> 0 | M40: -1 | N40: Finanziamenti netti vs soci e controllanti
A41: =input!A40 -> B.III.2.d.bis. Cred. vs Altri entro | B41: =$M41*input!B40 -> 0 | C41: =$M41*input!C40 -> 0 | D41: =$M41*input!D40 -> 10782.128 | E41: =$M41*input!E40 -> 343.435 | F41: =$M41*input!F40 -> 370.685 | G41: =$M41*input!G40 -> 324.796 | H41: =$M41*input!H40 -> 281.976 | I41: =$M41*input!I40 -> 278.258 | ... K41: =$M41*input!K40 -> 286.84 | M41: 1 | N41: Crediti diversi
...

Sheet RC
B1: =case!B1 -> 31/12/2024 | C1: =case!C1 -> 31/12/2023 | D1: =case!D1 -> 31/12/2022 | E1: =case!E1 -> 31/12/2021 | F1: =case!F1 -> 31/12/2020 | G1: =case!G1 -> 31/12/2019 | H1: =case!H1 -> 31/12/2018 | I1: =case!I1 -> 31/12/2017 | ... K1: =case!K1 -> 31/12/2015
A2: Stato Patrimoniale Attivo
A3: Attività operative
A4: Attività operative correnti
A5: Crediti verso clienti | B5: =SUMIF(case!$N:$N,$A5,case!B:B) -> 101879 | C5: =SUMIF(case!$N:$N,$A5,case!C:C) -> 90210 | D5: =SUMIF(case!$N:$N,$A5,case!D:D) -> 23706.719 | E5: =SUMIF(case!$N:$N,$A5,case!E:E) -> 29714.413 | F5: =SUMIF(case!$N:$N,$A5,case!F:F) -> 49086.977 | G5: =SUMIF(case!$N:$N,$A5,case!G:G) -> 70085.629 | H5: =SUMIF(case!$N:$N,$A5,case!H:H) -> 136291.51 | I5: =SUMIF(case!$N:$N,$A5,case!I:I) -> 129228.82 | J5: =SUMIF(case!$N:$N,$A5,case!J:J) -> 138605.74 | K5: =SUMIF(case!$N:$N,$A5,case!K:K) -> 142030.01
A6: Magazzino | B6: =SUMIF(case!$N:$N,$A6,case!B:B) -> 131166 | C6: =SUMIF(case!$N:$N,$A6,case!C:C) -> 118064 | D6: =SUMIF(case!$N:$N,$A6,case!D:D) -> 153759.14 | E6: =SUMIF(case!$N:$N,$A6,case!E:E) -> 132482.19 | F6: =SUMIF(case!$N:$N,$A6,case!F:F) -> 122437.39 | G6: =SUMIF(case!$N:$N,$A6,case!G:G) -> 119385.93 | H6: =SUMIF(case!$N:$N,$A6,case!H:H) -> 165935.34 | I6: =SUMIF(case!$N:$N,$A6,case!I:I) -> 122521.08 | J6: =SUMIF(case!$N:$N,$A6,case!J:J) -> 131111.25 | K6: =SUMIF(case!$N:$N,$A6,case!K:K) -> 127191.34
A7: Altre attività operative correnti | B7: =SUMIF(case!$N:$N,$A7,case!B:B) -> 321936 | C7: =SUMIF(case!$N:$N,$A7,case!C:C) -> 267775 | D7: =SUMIF(case!$N:$N,$A7,case!D:D) -> 17604.266 | E7: =SUMIF(case!$N:$N,$A7,case!E:E) -> 18782.062 | F7: =SUMIF(case!$N:$N,$A7,case!F:F) -> 8428.457 | G7: =SUMIF(case!$N:$N,$A7,case!G:G) -> 2544.949 | H7: =SUMIF(case!$N:$N,$A7,case!H:H) -> 4712.925 | I7: =SUMIF(case!$N:$N,$A7,case!I:I) -> 4013.273 | J7: =SUMIF(case!$N:$N,$A7,case!J:J) -> 2973.346 | K7: =SUMIF(case!$N:$N,$A7,case!K:K) -> 9881.25
A8: Totale attività operative correnti | B8: =SUM(B5:B7) -> 554981 | C8: =SUM(C5:C7) -> 476049 | D8: =SUM(D5:D7) -> 195070.13 | E8: =SUM(E5:E7) -> 180978.67 | F8: =SUM(F5:F7) -> 179952.82 | G8: =SUM(G5:G7) -> 192016.5 | H8: =SUM(H5:H7) -> 306939.78 | I8: =SUM(I5:I7) -> 255763.17 | ... K8: =SUM(K5:K7) -> 279102.59
A9: Immobilizzazioni operative nette
A10: Immobilizzazioni materiali nette | B10: =SUMIF(case!$N:$N,$A10,case!B:B) -> 247743 | C10: =SUMIF(case!$N:$N,$A10,case!C:C) -> 220617 | D10: =SUMIF(case!$N:$N,$A10,case!D:D) -> 224251.13 | E10: =SUMIF(case!$N:$N,$A10,case!E:E) -> 220459.24 | F10: =SUMIF(case!$N:$N,$A10,case!F:F) -> 220394.5 | G10: =SUMIF(case!$N:$N,$A10,case!G:G) -> 154055.72 | H10: =SUMIF(case!$N:$N,$A10,case!H:H) -> 149620.66 | I10: =SUMIF(case!$N:$N,$A10,case!I:I) -> 158524.65 | J10: =SUMIF(case!$N:$N,$A10,case!J:J) -> 145157.72 | K10: =SUMIF(case!$N:$N,$A10,case!K:K) -> 152948.57
A11: Immobilizzazioni immateriali nette | B11: =SUMIF(case!$N:$N,$A11,case!B:B) -> 1592262 | C11: =SUMIF(case!$N:$N,$A11,case!C:C) -> 90098 | D11: =SUMIF(case!$N:$N,$A11,case!D:D) -> 86779.886 | E11: =SUMIF(case!$N:$N,$A11,case!E:E) -> 89055.322 | F11: =SUMIF(case!$N:$N,$A11,case!F:F) -> 87656.701 | G11: =SUMIF(case!$N:$N,$A11,case!G:G) -> 13306.33 | H11: =SUMIF(case!$N:$N,$A11,case!H:H) -> 11674.413 | I11: =SUMIF(case!$N:$N,$A11,case!I:I) -> 12394.555 | J11: =SUMIF(case!$N:$N,$A11,case!J:J) -> 14257.563 | K11: =SUMIF(case!$N:$N,$A11,case!K:K) -> 16231.349
A12: Totale immobilizzazioni operative nette | B12: =SUM(B10:B11) -> 1840005 | C12: =SUM(C10:C11) -> 310715 | D12: =SUM(D10:D11) -> 311031.01 | E12: =SUM(E10:E11) -> 309514.56 | F12: =SUM(F10:F11) -> 308051.2 | G12: =SUM(G10:G11) -> 167362.05 | H12: =SUM(H10:H11) -> 161295.08 | I12: =SUM(I10:I11) -> 170919.21 | ... K12: =SUM(K10:K11) -> 169179.91
A13: Altre attività operative immobilizzate
A14: Crediti diversi | B14: =SUMIF(case!$N:$N,$A14,case!B:B) -> 0 | C14: =SUMIF(case!$N:$N,$A14,case!C:C) -> 0 | D14: =SUMIF(case!$N:$N,$A14,case!D:D) -> 10782.128 | E14: =SUMIF(case!$N:$N,$A14,case!E:E) -> 343.435 | F14: =SUMIF(case!$N:$N,$A14,case!F:F) -> 370.685 | G14: =SUMIF(case!$N:$N,$A14,case!G:G) -> 324.796 | H14: =SUMIF(case!$N:$N,$A14,case!H:H) -> 281.976 | I14: =SUMIF(case!$N:$N,$A14,case!I:I) -> 278.258 | J14: =SUMIF(case!$N:$N,$A14,case!J:J) -> 291.076 | K14: =SUMIF(case!$N:$N,$A14,case!K:K) -> 286.84
A15: Totale altre attività operative immobilizzate | B15: =SUM(B14) -> 0 | C15: =SUM(C14) -> 0 | D15: =SUM(D14) -> 10782.128 | E15: =SUM(E14) -> 343.435 | F15: =SUM(F14) -> 370.685 | G15: =SUM(G14) -> 324.796 | H15: =SUM(H14) -> 281.976 | I15: =SUM(I14) -> 278.258 | ... K15: =SUM(K14) -> 286.84
A16: Totale attività operative | B16: =B8+B12+B15 -> 2394986 | C16: =C8+C12+C15 -> 786764 | D16: =D8+D12+D15 -> 516883.27 | E16: =E8+E12+E15 -> 490836.66 | F16: =F8+F12+F15 -> 488374.71 | G16: =G8+G12+G15 -> 359703.35 | H16: =H8+H12+H15 -> 468516.83 | I16: =I8+I12+I15 -> 426960.64 | ... K16: =K8+K12+K15 -> 448569.35
A18: Attività fiscali
A19: Crediti fisco-previdenziali | B19: =SUMIF(case!$N:$N,$A19,case!B:B) -> 10412 | C19: =SUMIF(case!$N:$N,$A19,case!C:C) -> 8555 | D19: =SUMIF(case!$N:$N,$A19,case!D:D) -> 50852.584 | E19: =SUMIF(case!$N:$N,$A19,case!E:E) -> 25325.401 | F19: =SUMIF(case!$N:$N,$A19,case!F:F) -> 26513.908 | G19: =SUMIF(case!$N:$N,$A19,case!G:G) -> 3901.695 | H19: =SUMIF(case!$N:$N,$A19,case!H:H) -> 4891.5 | I19: =SUMIF(case!$N:$N,$A19,case!I:I) -> 3093.341 | J19: =SUMIF(case!$N:$N,$A19,case!J:J) -> 1080.503 | K19: =SUMIF(case!$N:$N,$A19,case!K:K) -> 1914.91
A20: Attività per imposte anticipate | B20: =SUMIF(case!$N:$N,$A20,case!B:B) -> 37784 | C20: =SUMIF(case!$N:$N,$A20,case!C:C) -> 23126 | D20: =SUMIF(case!$N:$N,$A20,case!D:D) -> 18985.47 | E20: =SUMIF(case!$N:$N,$A20,case!E:E) -> 14440.609 | F20: =SUMIF(case!$N:$N,$A20,case!F:F) -> 16501.79 | G20: =SUMIF(case!$N:$N,$A20,case!G:G) -> 16381.2 | H20: =SUMIF(case!$N:$N,$A20,case!H:H) -> 14957.316 | I20: =SUMIF(case!$N:$N,$A20,case!I:I) -> 13699.206 | J20: =SUMIF(case!$N:$N,$A20,case!J:J) -> 9127.07 | K20: =SUMIF(case!$N:$N,$A20,case!K:K) -> 6979.118
A21: Totale attività fiscali | B21: =SUM(B19:B20) -> 48196 | C21: =SUM(C19:C20) -> 31681 | D21: =SUM(D19:D20) -> 69838.054 | E21: =SUM(E19:E20) -> 39766.01 | F21: =SUM(F19:F20) -> 43015.698 | G21: =SUM(G19:G20) -> 20282.895 | H21: =SUM(H19:H20) -> 19848.816 | I21: =SUM(I19:I20) -> 16792.547 | ... K21: =SUM(K19:K20) -> 8894.028
A23: Attività accessorie
A24: Immobilizzazioni extra-operative | B24: =SUMIF(case!$N:$N,$A24,case!B:B) -> 0 | C24: =SUMIF(case!$N:$N,$A24,case!C:C) -> 0 | D24: =SUMIF(case!$N:$N,$A24,case!D:D) -> 0 | E24: =SUMIF(case!$N:$N,$A24,case!E:E) -> 0 | F24: =SUMIF(case!$N:$N,$A24,case!F:F) -> 0 | G24: =SUMIF(case!$N:$N,$A24,case!G:G) -> 0 | H24: =SUMIF(case!$N:$N,$A24,case!H:H) -> 0 | I24: =SUMIF(case!$N:$N,$A24,case!I:I) -> 0 | J24: =SUMIF(case!$N:$N,$A24,case!J:J) -> 0 | K24: =SUMIF(case!$N:$N,$A24,case!K:K) -> 0
A25: Partecipazioni | B25: =SUMIF(case!$N:$N,$A25,case!B:B) -> 1015828 | C25: =SUMIF(case!$N:$N,$A25,case!C:C) -> 559853 | D25: =SUMIF(case!$N:$N,$A25,case!D:D) -> 556283.77 | E25: =SUMIF(case!$N:$N,$A25,case!E:E) -> 484337.02 | F25: =SUMIF(case!$N:$N,$A25,case!F:F) -> 436771.36 | G25: =SUMIF(case!$N:$N,$A25,case!G:G) -> 185287.81 | H25: =SUMIF(case!$N:$N,$A25,case!H:H) -> 205707.91 | I25: =SUMIF(case!$N:$N,$A25,case!I:I) -> 232021.82 | J25: =SUMIF(case!$N:$N,$A25,case!J:J) -> 249459.61 | K25: =SUMIF(case!$N:$N,$A25,case!K:K) -> 248664.75
A26: Crediti vs controllate e collegate | B26: =SUMIF(case!$N:$N,$A26,case!B:B) -> 0 | C26: =SUMIF(case!$N:$N,$A26,case!C:C) -> 0 | D26: =SUMIF(case!$N:$N,$A26,case!D:D) -> 284157.73 | E26: =SUMIF(case!$N:$N,$A26,case!E:E) -> 184307.39 | F26: =SUMIF(case!$N:$N,$A26,case!F:F) -> 204222.62 | G26: =SUMIF(case!$N:$N,$A26,case!G:G) -> 68482.991 | H26: =SUMIF(case!$N:$N,$A26,case!H:H) -> 76639.783 | I26: =SUMIF(case!$N:$N,$A26,case!I:I) -> 63300.047 | J26: =SUMIF(case!$N:$N,$A26,case!J:J) -> 53087.503 | K26: =SUMIF(case!$N:$N,$A26,case!K:K) -> 53848.936
A27: Totale attività accessorie | B27: =SUM(B24:B26) -> 1015828 | C27: =SUM(C24:C26) -> 559853 | D27: =SUM(D24:D26) -> 840441.5 | E27: =SUM(E24:E26) -> 668644.41 | F27: =SUM(F24:F26) -> 640993.98 | G27: =SUM(G24:G26) -> 253770.8 | H27: =SUM(H24:H26) -> 282347.7 | I27: =SUM(I24:I26) -> 295321.87 | ... K27: =SUM(K24:K26) -> 302513.68
A29: Attività finanziarie
A30: Riserve strategiche di liquidità | B30: =SUMIF(case!$N:$N,$A30,case!B:B) -> 0 | C30: =SUMIF(case!$N:$N,$A30,case!C:C) -> 0 | D30: =SUMIF(case!$N:$N,$A30,case!D:D) -> 0 | E30: =SUMIF(case!$N:$N,$A30,case!E:E) -> 0 | F30: =SUMIF(case!$N:$N,$A30,case!F:F) -> 0 | G30: =SUMIF(case!$N:$N,$A30,case!G:G) -> 0 | H30: =SUMIF(case!$N:$N,$A30,case!H:H) -> 0 | I30: =SUMIF(case!$N:$N,$A30,case!I:I) -> 0 | J30: =SUMIF(case!$N:$N,$A30,case!J:J) -> 0 | K30: =SUMIF(case!$N:$N,$A30,case!K:K) -> 0
A31: Attività di tesoreria | B31: =SUMIF(case!$N:$N,$A31,case!B:B) -> 324406 | C31: =SUMIF(case!$N:$N,$A31,case!C:C) -> 296765 | D31: =SUMIF(case!$N:$N,$A31,case!D:D) -> 107677.51 | E31: =SUMIF(case!$N:$N,$A31,case!E:E) -> 101551.99 | F31: =SUMIF(case!$N:$N,$A31,case!F:F) -> 137974.04 | G31: =SUMIF(case!$N:$N,$A31,case!G:G) -> 107984.77 | H31: =SUMIF(case!$N:$N,$A31,case!H:H) -> 19903.7 | I31: =SUMIF(case!$N:$N,$A31,case!I:I) -> 49713.475 | J31: =SUMIF(case!$N:$N,$A31,case!J:J) -> 28066.97 | K31: =SUMIF(case!$N:$N,$A31,case!K:K) -> 8542.951
A32: Strumenti derivati attivi | B32: =SUMIF(case!$N:$N,$A32,case!B:B) -> 6904 | C32: =SUMIF(case!$N:$N,$A32,case!C:C) -> 0 | D32: =SUMIF(case!$N:$N,$A32,case!D:D) -> 1696.644 | E32: =SUMIF(case!$N:$N,$A32,case!E:E) -> 5609.937 | F32: =SUMIF(case!$N:$N,$A32,case!F:F) -> 623.72 | G32: =SUMIF(case!$N:$N,$A32,case!G:G) -> 68.101 | H32: =SUMIF(case!$N:$N,$A32,case!H:H) -> 347.477 | I32: =SUMIF(case!$N:$N,$A32,case!I:I) -> 30.892 | J32: =SUMIF(case!$N:$N,$A32,case!J:J) -> 1597.017 | K32: =SUMIF(case!$N:$N,$A32,case!K:K) -> 0
A33: Totale attività finanziarie | B33: =SUM(B30:B32) -> 331310 | C33: =SUM(C30:C32) -> 296765 | D33: =SUM(D30:D32) -> 109374.15 | E33: =SUM(E30:E32) -> 107161.92 | F33: =SUM(F30:F32) -> 138597.76 | G33: =SUM(G30:G32) -> 108052.87 | H33: =SUM(H30:H32) -> 20251.177 | I33: =SUM(I30:I32) -> 49744.367 | ... K33: =SUM(K30:K32) -> 8542.951
A35: Totale attivo | B35: =B16+B21+B27+B33 -> 3790320 | C35: =C16+C21+C27+C33 -> 1675063 | D35: =D16+D21+D27+D33 -> 1536537 | E35: =E16+E21+E27+E33 -> 1306409 | F35: =F16+F21+F27+F33 -> 1310982.1 | G35: =G16+G21+G27+G33 -> 741809.91 | H35: =H16+H21+H27+H33 -> 790964.52 | I35: =I16+I21+I27+I33 -> 788819.42 | ... K35: =K16+K21+K27+K33 -> 768520.01
A37: Check con totale attivo AIDA | B37: =case!B95 -> 3790320 | C37: =case!C95 -> 1675063 | D37: =case!D95 -> 1536537 | E37: =case!E95 -> 1308756.7 | F37: =case!F95 -> 1311132.3 | G37: =case!G95 -> 741974.82 | H37: =case!H95 -> 792683.74 | I37: =case!I95 -> 788836.85 | ... K37: =case!K95 -> 780383.29
A38: Differenza tra totale attivo e totale attivo AIDA | B38: =B37-B35 -> 0 | C38: =C37-C35 -> 0 | D38: =D37-D35 -> 0 | E38: =E37-E35 -> 2347.699 | F38: =F37-F35 -> 150.154 | G38: =G37-G35 -> 164.911 | H38: =H37-H35 -> 1719.228 | I38: =I37-I35 -> 17.433 | ... K38: =K37-K35 -> 11863.28
A39: Somma voci spostate nel passivo | B39: =case!B2+case!B46 -> 0 | C39: =case!C2+case!C46 -> 0 | D39: =case!D2+case!D46 -> 0 | E39: =case!E2+case!E46 -> 0 | F39: =case!F2+case!F46 -> 0 | G39: =case!G2+case!G46 -> 0 | H39: =case!H2+case!H46 -> 0 | I39: =case!I2+case!I46 -> 0 | ... K39: =case!K2+case!K46 -> 0
A40: Sbilancio | B40: =B38+B39 -> 0 | C40: =C38+C39 -> 0 | D40: =D38+D39 -> 0 | E40: =E38+E39 -> 2347.699 | F40: =F38+F39 -> 150.154 | G40: =G38+G39 -> 164.911 | H40: =H38+H39 -> 1719.228 | I40: =I38+I39 -> 17.433 | ... K40: =K38+K39 -> 11863.28
B44: =B1 -> 31/12/2024 | C44: =C1 -> 31/12/2023 | D44: =D1 -> 31/12/2022 | E44: =E1 -> 31/12/2021 | F44: =F1 -> 31/12/2020 | G44: =G1 -> 31/12/2019 | H44: =H1 -> 31/12/2018 | I44: =I1 -> 31/12/2017 | ... K44: =K1 -> 31/12/2015
A45: Stato Patrimoniale Passivo
A46: Passività operative
A47: Passività operative correnti | B47: =SUMIF(case!$N:$N,$A47,case!B:B) -> 0 | C47: =SUMIF(case!$N:$N,$A47,case!C:C) -> 0 | D47: =SUMIF(case!$N:$N,$A47,case!D:D) -> 0 | E47: =SUMIF(case!$N:$N,$A47,case!E:E) -> 0 | F47: =SUMIF(case!$N:$N,$A47,case!F:F) -> 0 | G47: =SUMIF(case!$N:$N,$A47,case!G:G) -> 0 | H47: =SUMIF(case!$N:$N,$A47,case!H:H) -> 0 | I47: =SUMIF(case!$N:$N,$A47,case!I:I) -> 0 | J47: =SUMIF(case!$N:$N,$A47,case!J:J) -> 0 | K47: =SUMIF(case!$N:$N,$A47,case!K:K) -> 0
A48: Debiti vs fornitori | B48: =SUMIF(case!$N:$N,$A48,case!B:B) -> 250274 | C48: =SUMIF(case!$N:$N,$A48,case!C:C) -> 182261 | D48: =SUMIF(case!$N:$N,$A48,case!D:D) -> 252136.23 | E48: =SUMIF(case!$N:$N,$A48,case!E:E) -> 190182.36 | F48: =SUMIF(case!$N:$N,$A48,case!F:F) -> 134849.12 | G48: =SUMIF(case!$N:$N,$A48,case!G:G) -> 139771.21 | H48: =SUMIF(case!$N:$N,$A48,case!H:H) -> 197078.86 | I48: =SUMIF(case!$N:$N,$A48,case!I:I) -> 142429.71 | J48: =SUMIF(case!$N:$N,$A48,case!J:J) -> 140877.26 | K48: =SUMIF(case!$N:$N,$A48,case!K:K) -> 154222
...

Sheet RF
B1: Rendiconto finanziario | C1: =case!B1 -> 31/12/2024 | D1: =case!C1 -> 31/12/2023 | E1: =case!D1 -> 31/12/2022 | F1: =case!E1 -> 31/12/2021 | G1: =case!F1 -> 31/12/2020 | H1: =case!G1 -> 31/12/2019 | I1: =case!H1 -> 31/12/2018 | J1: =case!I1 -> 31/12/2017 | ... L1: =case!K1 -> 31/12/2015
B2: Flussi di cassa della gestione operativa e accessoria
B3: Flussi di cassa della gestione operativa corrente
A4: + | B4: Reddito operativo | C4: ='RC'!B131 -> 60536 | D4: ='RC'!C131 -> 57190 | E4: ='RC'!D131 -> 11294.284 | F4: ='RC'!E131 -> 9288.812 | G4: ='RC'!F131 -> 3264.182 | H4: ='RC'!G131 -> 30663.78 | I4: ='RC'!H131 -> 33717.566 | J4: ='RC'!I131 -> 77298.709 | ... L4: ='RC'!K131 -> 51933.84
A5: ± | B5: Reddito gestioni accessoria e straordinaria | C5: ='RC'!B146 -> -43154 | D5: ='RC'!C146 -> -6813 | E5: ='RC'!D146 -> 39318.078 | F5: ='RC'!E146 -> 15698.284 | G5: ='RC'!F146 -> 7043.277 | H5: ='RC'!G146 -> -13924.696 | I5: ='RC'!H146 -> -19712.91 | J5: ='RC'!I146 -> -10378.498 | ... L5: ='RC'!K146 -> 6656.506
A6: + | B6: Riaggiunta ammortamenti | C6: =-'RC'!B124 -> 51303 | D6: =-'RC'!C124 -> 32661 | E6: =-'RC'!D124 -> 35625.263 | F6: =-'RC'!E124 -> 31971.207 | G6: =-'RC'!F124 -> 26000.365 | H6: =-'RC'!G124 -> 21147.856 | I6: =-'RC'!H124 -> 26935.278 | J6: =-'RC'!I124 -> 31141.093 | ... L6: =-'RC'!K124 -> 22820.98
A7: - | B7: (Imposte + Risparmio fiscale interessi netti) | C7: =-('RC'!B149+'RC'!B157) -> 17288.031 | D7: =-('RC'!C149+'RC'!C157) -> 4014.4472 | E7: =-('RC'!D149+'RC'!D157) -> 30410.509 | F7: =-('RC'!E149+'RC'!E157) -> 14134.253 | G7: =-('RC'!F149+'RC'!F157) -> 637.06043 | H7: =-('RC'!G149+'RC'!G157) -> 8050.9647 | I7: =-('RC'!H149+'RC'!H157) -> 3216.6355 | J7: =-('RC'!I149+'RC'!I157) -> 11187.544 | ... L7: =-('RC'!K149+'RC'!K157) -> 15271.082
A8: = | B8: EBITDA al netto delle imposte | C8: =C4+C5+C6-C7 -> 51396.969 | D8: =D4+D5+D6-D7 -> 79023.553 | E8: =E4+E5+E6-E7 -> 55827.116 | F8: =F4+F5+F6-F7 -> 42824.05 | G8: =G4+G5+G6-G7 -> 35670.764 | H8: =H4+H5+H6-H7 -> 29835.975 | I8: =I4+I5+I6-I7 -> 37723.299 | J8: =J4+J5+J6-J7 -> 86873.76 | ... L8: =L4+L5+L6-L7 -> 66140.244
B9: Rettifiche per determinare il flusso di cassa
B10: Variazione del CCON*
A11: - | B11: (Aumento) diminuzione crediti verso clienti | C11: =-1*('RC'!B5-'RC'!C5) -> -11669 | D11: =-1*('RC'!C5-'RC'!D5) -> -66503.281 | E11: =-1*('RC'!D5-'RC'!E5) -> 6007.694 | F11: =-1*('RC'!E5-'RC'!F5) -> 19372.564 | G11: =-1*('RC'!F5-'RC'!G5) -> 20998.652 | H11: =-1*('RC'!G5-'RC'!H5) -> 66205.883 | I11: =-1*('RC'!H5-'RC'!I5) -> -7062.696 | J11: =-1*('RC'!I5-'RC'!J5) -> 9376.927 | ... L11: =-1*('RC'!K5-'RC'!L5) -> -142030.01
A12: - | B12: (Aumento) diminuzione scorte magazzino | C12: =-1*('RC'!B6-'RC'!C6) -> -13102 | D12: =-1*('RC'!C6-'RC'!D6) -> 35695.143 | E12: =-1*('RC'!D6-'RC'!E6) -> -21276.95 | F12: =-1*('RC'!E6-'RC'!F6) -> -10044.808 | G12: =-1*('RC'!F6-'RC'!G6) -> -3051.458 | H12: =-1*('RC'!G6-'RC'!H6) -> 46549.412 | I12: =-1*('RC'!H6-'RC'!I6) -> -43414.255 | J12: =-1*('RC'!I6-'RC'!J6) -> 8590.164 | ... L12: =-1*('RC'!K6-'RC'!L6) -> -127191.34
A13: - | B13: (Aumento) diminuzione altre attività correnti | C13: =-1*('RC'!B7-'RC'!C7) -> -54161 | D13: =-1*('RC'!C7-'RC'!D7) -> -250170.73 | E13: =-1*('RC'!D7-'RC'!E7) -> 1177.796 | F13: =-1*('RC'!E7-'RC'!F7) -> -10353.605 | G13: =-1*('RC'!F7-'RC'!G7) -> -5883.508 | H13: =-1*('RC'!G7-'RC'!H7) -> 2167.976 | I13: =-1*('RC'!H7-'RC'!I7) -> -699.652 | J13: =-1*('RC'!I7-'RC'!J7) -> -1039.927 | ... L13: =-1*('RC'!K7-'RC'!L7) -> -9881.25
A14: + | B14: Aumento (diminuzione) debiti verso fornitori | C14: ='RC'!B48-'RC'!C48 -> 68013 | D14: ='RC'!C48-'RC'!D48 -> -69875.23 | E14: ='RC'!D48-'RC'!E48 -> 61953.867 | F14: ='RC'!E48-'RC'!F48 -> 55333.239 | G14: ='RC'!F48-'RC'!G48 -> -4922.085 | H14: ='RC'!G48-'RC'!H48 -> -57307.649 | I14: ='RC'!H48-'RC'!I48 -> 54649.144 | J14: ='RC'!I48-'RC'!J48 -> 1552.451 | ... L14: ='RC'!K48-'RC'!L48 -> 154222
A15: + | B15: Aumento (diminuzione) altre passività correnti | C15: ='RC'!B50-'RC'!C50 -> 8265 | D15: ='RC'!C50-'RC'!D50 -> 3030.782 | E15: ='RC'!D50-'RC'!E50 -> 556.815 | F15: ='RC'!E50-'RC'!F50 -> 5737.392 | G15: ='RC'!F50-'RC'!G50 -> -744.099 | H15: ='RC'!G50-'RC'!H50 -> 2756.409 | I15: ='RC'!H50-'RC'!I50 -> -681.304 | J15: ='RC'!I50-'RC'!J50 -> -929.062 | ... L15: ='RC'!K50-'RC'!L50 -> 11889.772
A16: - | B16: (Aumento) diminuzione attività fiscali | C16: =-1*('RC'!B21-'RC'!C21) -> -16515 | D16: =-1*('RC'!C21-'RC'!D21) -> 38157.054 | E16: =-1*('RC'!D21-'RC'!E21) -> -30072.044 | F16: =-1*('RC'!E21-'RC'!F21) -> 3249.688 | G16: =-1*('RC'!F21-'RC'!G21) -> -22732.803 | H16: =-1*('RC'!G21-'RC'!H21) -> -434.079 | I16: =-1*('RC'!H21-'RC'!I21) -> -3056.269 | J16: =-1*('RC'!I21-'RC'!J21) -> -6584.974 | ... L16: =-1*('RC'!K21-'RC'!L21) -> -8894.028
A17: + | B17: Aumento (diminuzione) passività fiscali | C17: ='RC'!B62-'RC'!C62 -> 92954 | D17: ='RC'!C62-'RC'!D62 -> -21855.557 | E17: ='RC'!D62-'RC'!E62 -> 4369.679 | F17: ='RC'!E62-'RC'!F62 -> -24420.619 | G17: ='RC'!F62-'RC'!G62 -> 35385.32 | H17: ='RC'!G62-'RC'!H62 -> 1510.859 | I17: ='RC'!H62-'RC'!I62 -> 5624.407 | J17: ='RC'!I62-'RC'!J62 -> -564.856 | ... L17: ='RC'!K62-'RC'!L62 -> 23945.142
A18: = | B18: (Aumento) diminuzione CCON* | C18: =SUM(C11:C17) -> 73785 | D18: =SUM(D11:D17) -> -331521.82 | E18: =SUM(E11:E17) -> 22716.857 | F18: =SUM(F11:F17) -> 38873.851 | G18: =SUM(G11:G17) -> 19050.019 | H18: =SUM(H11:H17) -> 61448.811 | I18: =SUM(I11:I17) -> 5359.375 | J18: =SUM(J11:J17) -> 10400.723 | ... L18: =SUM(L11:L17) -> -97939.712
A19: + | B19: Aumento (diminuzione) fondo TFR | C19: ='RC'!B53-'RC'!C53 -> -1064 | D19: ='RC'!C53-'RC'!D53 -> -2654.145 | E19: ='RC'!D53-'RC'!E53 -> 39.782 | F19: ='RC'!E53-'RC'!F53 -> -1322.841 | G19: ='RC'!F53-'RC'!G53 -> -2188.46 | H19: ='RC'!G53-'RC'!H53 -> -1299.644 | I19: ='RC'!H53-'RC'!I53 -> -1203.192 | J19: ='RC'!I53-'RC'!J53 -> -1115.942 | ... L19: ='RC'!K53-'RC'!L53 -> 17851.924
A20: - | B20: (Aumento) diminuzione altre attività operative immobilizzate | C20: =-1*('RC'!B15-'RC'!C15) -> 0 | D20: =-1*('RC'!C15-'RC'!D15) -> 10782.128 | E20: =-1*('RC'!D15-'RC'!E15) -> -10438.693 | F20: =-1*('RC'!E15-'RC'!F15) -> 27.25 | G20: =-1*('RC'!F15-'RC'!G15) -> -45.889 | H20: =-1*('RC'!G15-'RC'!H15) -> -42.82 | I20: =-1*('RC'!H15-'RC'!I15) -> -3.718 | J20: =-1*('RC'!I15-'RC'!J15) -> 12.818 | ... L20: =-1*('RC'!K15-'RC'!L15) -> -286.84
A21: + | B21: Aumento (diminuzione) altre passività operative consolidate | C21: ='RC'!B54-'RC'!C54 -> 0 | D21: ='RC'!C54-'RC'!D54 -> 0 | E21: ='RC'!D54-'RC'!E54 -> 0 | F21: ='RC'!E54-'RC'!F54 -> 0 | G21: ='RC'!F54-'RC'!G54 -> 0 | H21: ='RC'!G54-'RC'!H54 -> 0 | I21: ='RC'!H54-'RC'!I54 -> 0 | J21: ='RC'!I54-'RC'!J54 -> 0 | ... L21: ='RC'!K54-'RC'!L54 -> 0
A22: = | B22: Totale rettifiche | C22: =SUM(C18:C21) -> 72721 | D22: =SUM(D18:D21) -> -323393.84 | E22: =SUM(E18:E21) -> 12317.946 | F22: =SUM(F18:F21) -> 37578.26 | G22: =SUM(G18:G21) -> 16815.67 | H22: =SUM(H18:H21) -> 60106.347 | I22: =SUM(I18:I21) -> 4152.465 | J22: =SUM(J18:J21) -> 9297.599 | ... L22: =SUM(L18:L21) -> -80374.628
A23: = | B23: Flussi di cassa netti gestione operativa corrente, acc e straord. | C23: =C8+C22 -> 124117.97 | D23: =D8+D22 -> -244370.29 | E23: =E8+E22 -> 68145.062 | F23: =F8+F22 -> 80402.31 | G23: =G8+G22 -> 52486.434 | H23: =H8+H22 -> 89942.322 | I23: =I8+I22 -> 41875.764 | J23: =J8+J22 -> 96171.359 | ... L23: =L8+L22 -> -14234.384
B24: Flussi di cassa della gestione investimenti
A25: - | B25: (Aumento) diminuzione Immobilizzazioni operative nette | C25: =-1*('RC'!B12-'RC'!C12) -> -1529290 | D25: =-1*('RC'!C12-'RC'!D12) -> 316.013 | E25: =-1*('RC'!D12-'RC'!E12) -> -1516.455 | F25: =-1*('RC'!E12-'RC'!F12) -> -1463.357 | G25: =-1*('RC'!F12-'RC'!G12) -> -140689.15 | H25: =-1*('RC'!G12-'RC'!H12) -> -6066.974 | I25: =-1*('RC'!H12-'RC'!I12) -> 9624.134 | J25: =-1*('RC'!I12-'RC'!J12) -> -11503.925 | ... L25: =-1*('RC'!K12-'RC'!L12) -> -169179.91
A26: - | B26: (Aumento) diminuzione attività accessorie | C26: =-1*('RC'!B27-'RC'!C27) -> -455975 | D26: =-1*('RC'!C27-'RC'!D27) -> 280588.5 | E26: =-1*('RC'!D27-'RC'!E27) -> -171797.09 | F26: =-1*('RC'!E27-'RC'!F27) -> -27650.428 | G26: =-1*('RC'!F27-'RC'!G27) -> -387223.18 | H26: =-1*('RC'!G27-'RC'!H27) -> 28576.895 | I26: =-1*('RC'!H27-'RC'!I27) -> 12974.171 | J26: =-1*('RC'!I27-'RC'!J27) -> 7225.244 | ... L26: =-1*('RC'!K27-'RC'!L27) -> -302513.68
A27: + | B27: Aumento (diminuzione) debiti vs controllate e collegate | C27: ='RC'!B66-'RC'!C66 -> 0 | D27: ='RC'!C66-'RC'!D66 -> -395029.19 | E27: ='RC'!D66-'RC'!E66 -> 220748.76 | F27: ='RC'!E66-'RC'!F66 -> 32754.021 | G27: ='RC'!F66-'RC'!G66 -> 37594.96 | H27: ='RC'!G66-'RC'!H66 -> 35978.454 | I27: ='RC'!H66-'RC'!I66 -> 21451.219 | J27: ='RC'!I66-'RC'!J66 -> -7620.477 | ... L27: ='RC'!K66-'RC'!L66 -> 49593.984
A28: - | B28: (Ammortamenti) | C28: ='RC'!B124 -> -51303 | D28: ='RC'!C124 -> -32661 | E28: ='RC'!D124 -> -35625.263 | F28: ='RC'!E124 -> -31971.207 | G28: ='RC'!F124 -> -26000.365 | H28: ='RC'!G124 -> -21147.856 | I28: ='RC'!H124 -> -26935.278 | J28: ='RC'!I124 -> -31141.093 | ... L28: ='RC'!K124 -> -22820.98
A29: + | B29: Aumento (diminuzione) riserve da rivalutazione | C29: ='RC'!B80-'RC'!C80 -> 0 | D29: ='RC'!C80-'RC'!D80 -> -15208.961 | E29: ='RC'!D80-'RC'!E80 -> -2812.271 | F29: ='RC'!E80-'RC'!F80 -> 3582.652 | G29: ='RC'!F80-'RC'!G80 -> -1033.323 | H29: ='RC'!G80-'RC'!H80 -> 0 | I29: ='RC'!H80-'RC'!I80 -> 0 | J29: ='RC'!I80-'RC'!J80 -> 0 | ... L29: ='RC'!K80-'RC'!L80 -> 15471.903
A30: = | B30: Flussi di cassa netti della gestione investimenti | C30: =SUM(C25:C29) -> -2036568 | D30: =SUM(D25:D29) -> -161994.63 | E30: =SUM(E25:E29) -> 8997.674 | F30: =SUM(F25:F29) -> -24748.319 | G30: =SUM(G25:G29) -> -517351.06 | H30: =SUM(H25:H29) -> 37340.519 | I30: =SUM(I25:I29) -> 17114.246 | J30: =SUM(J25:J29) -> -43040.251 | ... L30: =SUM(L25:L29) -> -429448.69
A31: = | B31: Free cash flow to the firm (FCFF) | C31: =C23+C30 -> -1912450 | D31: =D23+D30 -> -406364.92 | E31: =E23+E30 -> 77142.736 | F31: =F23+F30 -> 55653.991 | G31: =G23+G30 -> -464864.63 | H31: =H23+H30 -> 127282.84 | I31: =I23+I30 -> 58990.01 | J31: =J23+J30 -> 53131.108 | ... L31: =L23+L30 -> -443683.08
B32: Flussi di cassa della gestione finanziaria
B33: Debito e attività finanziarie (esclusa tesoreria)
A34: - | B34: (Oneri finanziari netti) | C34: ='RC'!B140 -> -333886 | D34: ='RC'!C140 -> -113236 | E34: ='RC'!D140 -> -41465.99 | F34: ='RC'!E140 -> -33466.263 | G34: ='RC'!F140 -> -65444.809 | H34: ='RC'!G140 -> -4198.972 | I34: ='RC'!H140 -> -3379.875 | J34: ='RC'!I140 -> -5634.534 | ... L34: ='RC'!K140 -> -3431.708
A35: + | B35: Risparmio fiscale interessi netti | C35: =-'RC'!B157 -> 8875.0313 | D35: =-'RC'!C157 -> 2581.4472 | E35: =-'RC'!D157 -> 39016.608 | F35: =-'RC'!E157 -> 11277.048 | G35: =-'RC'!F157 -> 345.75843 | H35: =-'RC'!G157 -> -4052.8963 | I35: =-'RC'!H157 -> -1500.6165 | J35: =-'RC'!I157 -> -1132.7099 | ... L35: =-'RC'!K157 -> -1013.1259
A36: + | B36: Strumenti derivati: (aumento) diminuzione attivi + aumento (diminuzione) passivi | C36: =-('RC'!B32-'RC'!C32)+('RC'!B72-'RC'!C72) -> -20955 | D36: =-('RC'!C32-'RC'!D32)+('RC'!C72-'RC'!D72) -> 2971.912 | E36: =-('RC'!D32-'RC'!E32)+('RC'!D72-'RC'!E72) -> 18027.567 | F36: =-('RC'!E32-'RC'!F32)+('RC'!E72-'RC'!F72) -> -6513.5 | G36: =-('RC'!F32-'RC'!G32)+('RC'!F72-'RC'!G72) -> 1456.109 | H36: =-('RC'!G32-'RC'!H32)+('RC'!G72-'RC'!H72) -> 403.332 | I36: =-('RC'!H32-'RC'!I32)+('RC'!H72-'RC'!I72) -> -837.062 | J36: =-('RC'!I32-'RC'!J32)+('RC'!I72-'RC'!J72) -> 1941.187 | ... L36: =-('RC'!K32-'RC'!L32)+('RC'!K72-'RC'!L72) -> 0
A37: + | B37: Aumento (diminuzione) debiti struttturali a medio-lungo | C37: ='RC'!B69-'RC'!C69 -> 722110 | D37: ='RC'!C69-'RC'!D69 -> 703519 | E37: ='RC'!D69-'RC'!E69 -> -725617.18 | F37: ='RC'!E69-'RC'!F69 -> -54874.991 | G37: ='RC'!F69-'RC'!G69 -> 780492.17 | H37: ='RC'!G69-'RC'!H69 -> 0 | I37: ='RC'!H69-'RC'!I69 -> -55779.956 | J37: ='RC'!I69-'RC'!J69 -> -24089.8 | ... L37: ='RC'!K69-'RC'!L69 -> 103275.9
A38: + | B38: Aumento (diminuzione) debiti strutturali a breve | C38: ='RC'!B70-'RC'!C70 -> 37027 | D38: ='RC'!C70-'RC'!D70 -> 37414.159 | E38: ='RC'!D70-'RC'!E70 -> 12666.575 | F38: ='RC'!E70-'RC'!F70 -> -6302.069 | G38: ='RC'!F70-'RC'!G70 -> 18706.413 | H38: ='RC'!G70-'RC'!H70 -> -20459.546 | I38: ='RC'!H70-'RC'!I70 -> -79510.883 | J38: ='RC'!I70-'RC'!J70 -> 20497.531 | ... L38: ='RC'!K70-'RC'!L70 -> 100505.1
A39: - | B39: (Aumento) diminuzione riserve strategiche di liquidità | C39: =-('RC'!B30-'RC'!C30) -> 0 | D39: =-('RC'!C30-'RC'!D30) -> 0 | E39: =-('RC'!D30-'RC'!E30) -> 0 | F39: =-('RC'!E30-'RC'!F30) -> 0 | G39: =-('RC'!F30-'RC'!G30) -> 0 | H39: =-('RC'!G30-'RC'!H30) -> 0 | I39: =-('RC'!H30-'RC'!I30) -> 0 | J39: =-('RC'!I30-'RC'!J30) -> 0 | ... L39: =-('RC'!K30-'RC'!L30) -> 0
A40: = | B40: Flussi di cassa netti sul debito netto (esclusa tesoreria) (FCDN) | C40: =SUM(C34:C39) -> 413171.03 | D40: =SUM(D34:D39) -> 633250.52 | E40: =SUM(E34:E39) -> -697372.42 | F40: =SUM(F34:F39) -> -89879.775 | G40: =SUM(G34:G39) -> 735555.64 | H40: =SUM(H34:H39) -> -28308.082 | I40: =SUM(I34:I39) -> -141008.39 | J40: =SUM(J34:J39) -> -8418.3259 | ... L40: =SUM(L34:L39) -> 199336.16
...

Sheet ind
A1: INDICATORI FINANZIARI | B1: =RF!C1 -> 31/12/2024 | C1: =RF!D1 -> 31/12/2023 | D1: =RF!E1 -> 31/12/2022 | E1: =RF!F1 -> 31/12/2021 | F1: =RF!G1 -> 31/12/2020 | G1: =RF!H1 -> 31/12/2019 | H1: =RF!I1 -> 31/12/2018 | I1: =RF!J1 -> 31/12/2017 | ... K1: =RF!L1 -> 31/12/2015
A2: valori patrimoniali medie t-1 per attenuare variazioni significativi
A3: RLA (redd. gest OFA) | B3: ='RC'!B131+'RC'!B140+'RC'!B144 -> -271350 | C3: ='RC'!C131+'RC'!C140+'RC'!C144 -> -55571 | D3: ='RC'!D131+'RC'!D140+'RC'!D144 -> 22828.294 | E3: ='RC'!E131+'RC'!E140+'RC'!E144 -> -8349.646 | F3: ='RC'!F131+'RC'!F140+'RC'!F144 -> -54355.359 | G3: ='RC'!G131+'RC'!G140+'RC'!G144 -> 33258.555 | H3: ='RC'!H131+'RC'!H140+'RC'!H144 -> 37150.588 | I3: ='RC'!I131+'RC'!I140+'RC'!I144 -> 79225.107 | ... K3: ='RC'!K131+'RC'!K140+'RC'!K144 -> 54747.826
A4: Reddito operativo | B4: ='RC'!B131 -> 60536 | C4: ='RC'!C131 -> 57190 | D4: ='RC'!D131 -> 11294.284 | E4: ='RC'!E131 -> 9288.812 | F4: ='RC'!F131 -> 3264.182 | G4: ='RC'!G131 -> 30663.78 | H4: ='RC'!H131 -> 33717.566 | I4: ='RC'!I131 -> 77298.709 | ... K4: ='RC'!K131 -> 51933.84
A5: EBITDA(MOL) | B5: ='RC'!B123 -> 119175 | C5: ='RC'!C123 -> 82113 | D5: ='RC'!D123 -> 37444.691 | E5: ='RC'!E123 -> 45295.227 | F5: ='RC'!F123 -> 30724.468 | G5: ='RC'!G123 -> 59292.527 | H5: ='RC'!H123 -> 62458.988 | I5: ='RC'!I123 -> 111262.03 | ... K5: ='RC'!K123 -> 78727.516
A6: Reddito netto | B6: ='RC'!B150 -> -324917 | C6: ='RC'!C150 -> -64292 | D6: ='RC'!D150 -> 17752.471 | E6: ='RC'!E150 -> -11336.372 | F6: ='RC'!F150 -> -55428.652 | G6: ='RC'!G150 -> 436.251 | H6: ='RC'!H150 -> 5907.529 | I6: ='RC'!I150 -> 48965.423 | ... K6: ='RC'!K150 -> 38874.43
A7: Ricavi | B7: ='RC'!B111 -> 700351 | C7: ='RC'!C111 -> 567524 | D7: ='RC'!D111 -> 731617.37 | E7: ='RC'!E111 -> 575309.43 | F7: ='RC'!F111 -> 470766.3 | G7: ='RC'!G111 -> 599353.35 | H7: ='RC'!H111 -> 601111.28 | I7: ='RC'!I111 -> 658456.38 | ... K7: ='RC'!K111 -> 617897.5
A8: Ricavi t-1 | B8: ='RC'!C111 -> 567524 | C8: ='RC'!D111 -> 731617.37 | D8: ='RC'!E111 -> 575309.43 | E8: ='RC'!F111 -> 470766.3 | F8: ='RC'!G111 -> 599353.35 | G8: ='RC'!H111 -> 601111.28 | H8: ='RC'!I111 -> 658456.38 | I8: ='RC'!J111 -> 649016.11 | ... K8: ='RC'!L111 -> 0
A9: Ricavi con IVA gg | B9: =B7*1.22/365 -> 2340.8992 | C9: =C7*1.22/365 -> 1896.9295 | D9: =D7*1.22/365 -> 2445.406 | E9: =E7*1.22/365 -> 1922.9521 | F9: =F7*1.22/365 -> 1573.5202 | G9: =G7*1.22/365 -> 2003.318 | H9: =H7*1.22/365 -> 2009.1939 | I9: =I7*1.22/365 -> 2200.8679 | ... K9: =K7*1.22/365 -> 2065.3012
A10: Acquisti | B10: ='RC'!B116 -> -481014 | C10: ='RC'!C116 -> -384827 | D10: ='RC'!D116 -> -612180.15 | E10: ='RC'!E116 -> -449495.95 | F10: ='RC'!F116 -> -357984.27 | G10: ='RC'!G116 -> -400315.34 | H10: ='RC'!H116 -> -494524.11 | I10: ='RC'!I116 -> -448998.95 | ... K10: ='RC'!K116 -> -453576.4
A11: Acquisti con IVA gg | B11: ='RC'!B116*1.22/365 -> -1607.7728 | C11: ='RC'!C116*1.22/365 -> -1286.2711 | D11: ='RC'!D116*1.22/365 -> -2046.1912 | E11: ='RC'!E116*1.22/365 -> -1502.4248 | F11: ='RC'!F116*1.22/365 -> -1196.5501 | G11: ='RC'!G116*1.22/365 -> -1338.0403 | H11: ='RC'!H116*1.22/365 -> -1652.9299 | I11: ='RC'!I116*1.22/365 -> -1500.7636 | ... K11: ='RC'!K116*1.22/365 -> -1516.0636
A12: Costo del venduto gg medio | B12: =AVERAGE('RC'!B120:C120)/365 -> -1198.6753 | C12: =AVERAGE('RC'!C120:D120)/365 -> -1362.4962 | D12: =AVERAGE('RC'!D120:E120)/365 -> -1398.7047 | E12: =AVERAGE('RC'!E120:F120)/365 -> -1075.4576 | F12: =AVERAGE('RC'!F120:G120)/365 -> -1098.3528 | G12: =AVERAGE('RC'!G120:H120)/365 -> -1230.1022 | H12: =AVERAGE('RC'!H120:I120)/365 -> -1244.7931 | I12: =AVERAGE('RC'!I120:J120)/365 -> -1245.1908 | ... K12: =AVERAGE('RC'!K120:L120)/365 -> -1234.3372
A13: Costo del personale gg medio | B13: =AVERAGE('RC'!B122:C122)/365 -> -262.40274 | C13: =AVERAGE('RC'!C122:D122)/365 -> -253.37189 | D13: =AVERAGE('RC'!D122:E122)/365 -> -278.26363 | E13: =AVERAGE('RC'!E122:F122)/365 -> -253.3863 | F13: =AVERAGE('RC'!F122:G122)/365 -> -244.25356 | G13: =AVERAGE('RC'!G122:H122)/365 -> -247.587 | H13: =AVERAGE('RC'!H122:I122)/365 -> -242.66804 | I13: =AVERAGE('RC'!I122:J122)/365 -> -247.94772 | ... K13: =AVERAGE('RC'!K122:L122)/365 -> -242.84087
A14: AON* medio | B14: =AVERAGE('RC'!B93,'RC'!C93) -> 1292505.5 | C14: =AVERAGE('RC'!C93,'RC'!D93) -> 402682.09 | D14: =AVERAGE('RC'!D93,'RC'!E93) -> 246543.92 | E14: =AVERAGE('RC'!E93,'RC'!F93) -> 270002.12 | F14: =AVERAGE('RC'!F93,'RC'!G93) -> 226122.83 | G14: =AVERAGE('RC'!G93,'RC'!H93) -> 191205.77 | H14: =AVERAGE('RC'!H93,'RC'!I93) -> 225113.76 | I14: =AVERAGE('RC'!I93,'RC'!J93) -> 230898.89 | ... K14: =AVERAGE('RC'!K93,'RC'!L93) -> 249554.54
A15: AON* init | B15: ='RC'!C93 -> 564221 | C15: ='RC'!D93 -> 241143.17 | D15: ='RC'!E93 -> 251944.66 | E15: ='RC'!F93 -> 288059.57 | F15: ='RC'!G93 -> 164186.08 | G15: ='RC'!H93 -> 218225.46 | H15: ='RC'!I93 -> 232002.06 | I15: ='RC'!J93 -> 229795.73 | ... K15: ='RC'!L93 -> 0
A16: AON* fin | B16: ='RC'!B93 -> 2020790 | C16: ='RC'!C93 -> 564221 | D16: ='RC'!D93 -> 241143.17 | E16: ='RC'!E93 -> 251944.66 | F16: ='RC'!F93 -> 288059.57 | G16: ='RC'!G93 -> 164186.08 | H16: ='RC'!H93 -> 218225.46 | I16: ='RC'!I93 -> 232002.06 | ... K16: ='RC'!K93 -> 249554.54
A17: Reddito att.acc (prov-oneri acc) | B17: ='RC'!B144 -> 2000 | C17: ='RC'!C144 -> 475 | D17: ='RC'!D144 -> 53000 | E17: ='RC'!E144 -> 15827.805 | F17: ='RC'!F144 -> 7825.268 | G17: ='RC'!G144 -> 6793.747 | H17: ='RC'!H144 -> 6812.897 | I17: ='RC'!I144 -> 7560.932 | ... K17: ='RC'!K144 -> 6245.694
A18: AACCN media(ris gest acc) | B18: =AVERAGE('RC'!B94,'RC'!C94) -> 787840.5 | C18: =AVERAGE('RC'!C94,'RC'!D94) -> 502632.66 | D18: =AVERAGE('RC'!D94,'RC'!E94) -> 469888.15 | E18: =AVERAGE('RC'!E94,'RC'!F94) -> 496915.78 | F18: =AVERAGE('RC'!F94,'RC'!G94) -> 324653.46 | G18: =AVERAGE('RC'!G94,'RC'!H94) -> 182117.03 | H18: =AVERAGE('RC'!H94,'RC'!I94) -> 231607.4 | I18: =AVERAGE('RC'!I94,'RC'!J94) -> 248622.48 | ... K18: =AVERAGE('RC'!K94,'RC'!L94) -> 252919.7
A19: AACC medie(solo attività) | B19: =AVERAGE('RC'!B27,'RC'!C27) -> 787840.5 | C19: =AVERAGE('RC'!C27,'RC'!D27) -> 700147.25 | D19: =AVERAGE('RC'!D27,'RC'!E27) -> 754542.96 | E19: =AVERAGE('RC'!E27,'RC'!F27) -> 654819.2 | F19: =AVERAGE('RC'!F27,'RC'!G27) -> 447382.39 | G19: =AVERAGE('RC'!G27,'RC'!H27) -> 268059.25 | H19: =AVERAGE('RC'!H27,'RC'!I27) -> 288834.78 | I19: =AVERAGE('RC'!I27,'RC'!J27) -> 298934.49 | ... K19: =AVERAGE('RC'!K27,'RC'!L27) -> 302513.68
A20: AACC finali | B20: ='RC'!B27 -> 1015828 | C20: ='RC'!C27 -> 559853 | D20: ='RC'!D27 -> 840441.5 | E20: ='RC'!E27 -> 668644.41 | F20: ='RC'!F27 -> 640993.98 | G20: ='RC'!G27 -> 253770.8 | H20: ='RC'!H27 -> 282347.7 | I20: ='RC'!I27 -> 295321.87 | ... K20: ='RC'!K27 -> 302513.68
A21: PACC medie (solo passivo) | B21: =AVERAGE('RC'!B66,'RC'!C66) -> 0 | C21: =AVERAGE('RC'!C66,'RC'!D66) -> 197514.59 | D21: =AVERAGE('RC'!D66,'RC'!E66) -> 284654.81 | E21: =AVERAGE('RC'!E66,'RC'!F66) -> 157903.42 | F21: =AVERAGE('RC'!F66,'RC'!G66) -> 122728.93 | G21: =AVERAGE('RC'!G66,'RC'!H66) -> 85942.221 | H21: =AVERAGE('RC'!H66,'RC'!I66) -> 57227.385 | I21: =AVERAGE('RC'!I66,'RC'!J66) -> 50312.014 | ... K21: =AVERAGE('RC'!K66,'RC'!L66) -> 49593.984
A22: PACC finali (solo passivo) | B22: ='RC'!B66 -> 0 | C22: ='RC'!C66 -> 0 | D22: ='RC'!D66 -> 395029.19 | E22: ='RC'!E66 -> 174280.43 | F22: ='RC'!F66 -> 141526.41 | G22: ='RC'!G66 -> 103931.45 | H22: ='RC'!H66 -> 67952.994 | I22: ='RC'!I66 -> 46501.775 | ... K22: ='RC'!K66 -> 49593.984
A23: ris gest str | B23: ='RC'!B145 -> -45154 | C23: ='RC'!C145 -> -7288 | D23: ='RC'!D145 -> -13681.922 | E23: ='RC'!E145 -> -129.521 | F23: ='RC'!F145 -> -781.991 | G23: ='RC'!G145 -> -20718.443 | H23: ='RC'!H145 -> -26525.807 | I23: ='RC'!I145 -> -17939.43 | ... K23: ='RC'!K145 -> 410.812
A24: PFN (ris gest fin) | B24: =B30-B31 -> 840524.5 | C24: =C30-C31 -> 207845.21 | D24: =D30-D31 -> 280960.7 | E24: =E30-E31 -> 647119.23 | F24: =F30-F31 -> 277420.77 | G24: =G30-G31 -> -53843.292 | H24: =H30-H31 -> 53384.411 | I24: =I30-I31 -> 118192.27 | ... K24: =K30-K31 -> 195238.04
A25: DEBn | B25: =IF(B24>0, B24, 0) -> 840524.5 | C25: =IF(C24>0, C24, 0) -> 207845.21 | D25: =IF(D24>0, D24, 0) -> 280960.7 | E25: =IF(E24>0, E24, 0) -> 647119.23 | F25: =IF(F24>0, F24, 0) -> 277420.77 | G25: =IF(G24>0, G24, 0) -> 0 | H25: =IF(H24>0, H24, 0) -> 53384.411 | I25: =IF(I24>0, I24, 0) -> 118192.27 | ... K25: =IF(K24>0, K24, 0) -> 195238.04
A26: LIQn | B26: =IF(B24<0, -B24, 0) -> 0 | C26: =IF(C24<0, C24, 0) -> 0 | D26: =IF(D24<0, D24, 0) -> 0 | E26: =IF(E24<0, E24, 0) -> 0 | F26: =IF(F24<0, F24, 0) -> 0 | G26: =IF(G24<0, G24, 0) -> -53843.292 | H26: =IF(H24<0, H24, 0) -> 0 | I26: =IF(I24<0, I24, 0) -> 0 | J26: =IF(J24<0, J24, 0) -> 0 | K26: =IF(K24<0, K24, 0) -> 0
A27: oneri finanziari | B27: ='RC'!B138 -> -355850 | C27: ='RC'!C138 -> -135795 | D27: ='RC'!D138 -> -57535.862 | E27: ='RC'!E138 -> -41740 | F27: ='RC'!F138 -> -69507.699 | G27: ='RC'!G138 -> -5823.751 | H27: ='RC'!H138 -> -4557.97 | I27: ='RC'!I138 -> -2723.619 | ... K27: ='RC'!K138 -> -4104.179
A28: interessi attivi | B28: ='RC'!B137 -> 29006 | C28: ='RC'!C137 -> 22875 | D28: ='RC'!D137 -> 7976.72 | E28: ='RC'!E137 -> 6455.647 | F28: ='RC'!F137 -> 7773.098 | G28: ='RC'!G137 -> 851.751 | H28: ='RC'!H137 -> 1026.672 | I28: ='RC'!I137 -> 1144.668 | ... K28: ='RC'!K137 -> 1503.171
A29: imposta | B29: ='RC'!B149 -> -8413 | C29: ='RC'!C149 -> -1433 | D29: ='RC'!D149 -> 8606.099 | E29: ='RC'!E149 -> -2857.205 | F29: ='RC'!F149 -> -291.302 | G29: ='RC'!G149 -> -12103.861 | H29: ='RC'!H149 -> -4717.252 | I29: ='RC'!I149 -> -12320.254 | ... K29: ='RC'!K149 -> -16284.208
A30: Debito lordo medio(pass. gest. fin) | B30: =AVERAGE('RC'!B73,'RC'!C73) -> 1154562 | C30: =AVERAGE('RC'!C73,'RC'!D73) -> 410914.79 | D30: =AVERAGE('RC'!D73,'RC'!E73) -> 389228.74 | E30: =AVERAGE('RC'!E73,'RC'!F73) -> 769999.07 | F30: =AVERAGE('RC'!F73,'RC'!G73) -> 400746.09 | G30: =AVERAGE('RC'!G73,'RC'!H73) -> 10308.73 | H30: =AVERAGE('RC'!H73,'RC'!I73) -> 88382.183 | I30: =AVERAGE('RC'!I73,'RC'!J73) -> 157896.44 | ... K30: =AVERAGE('RC'!K73,'RC'!L73) -> 203780.99
A31: Liq. lorda media(att. gest fin) | B31: =AVERAGE('RC'!B33,'RC'!C33) -> 314037.5 | C31: =AVERAGE('RC'!C33,'RC'!D33) -> 203069.58 | D31: =AVERAGE('RC'!D33,'RC'!E33) -> 108268.04 | E31: =AVERAGE('RC'!E33,'RC'!F33) -> 122879.84 | F31: =AVERAGE('RC'!F33,'RC'!G33) -> 123325.32 | G31: =AVERAGE('RC'!G33,'RC'!H33) -> 64152.022 | H31: =AVERAGE('RC'!H33,'RC'!I33) -> 34997.772 | I31: =AVERAGE('RC'!I33,'RC'!J33) -> 39704.177 | ... K31: =AVERAGE('RC'!K33,'RC'!L33) -> 8542.951
A32: Crediti commerciali medi | B32: =AVERAGE('RC'!B5:C5) -> 96044.5 | C32: =AVERAGE('RC'!C5:D5) -> 56958.359 | D32: =AVERAGE('RC'!D5:E5) -> 26710.566 | E32: =AVERAGE('RC'!E5:F5) -> 39400.695 | F32: =AVERAGE('RC'!F5:G5) -> 59586.303 | G32: =AVERAGE('RC'!G5:H5) -> 103188.57 | H32: =AVERAGE('RC'!H5:I5) -> 132760.16 | I32: =AVERAGE('RC'!I5:J5) -> 133917.28 | ... K32: =AVERAGE('RC'!K5:L5) -> 142030.01
A33: Debiti commerciali medi | B33: =AVERAGE('RC'!B48,'RC'!C48) -> 216267.5 | C33: =AVERAGE('RC'!C48,'RC'!D48) -> 217198.61 | D33: =AVERAGE('RC'!D48,'RC'!E48) -> 221159.3 | E33: =AVERAGE('RC'!E48,'RC'!F48) -> 162515.74 | F33: =AVERAGE('RC'!F48,'RC'!G48) -> 137310.17 | G33: =AVERAGE('RC'!G48,'RC'!H48) -> 168425.03 | H33: =AVERAGE('RC'!H48,'RC'!I48) -> 169754.29 | I33: =AVERAGE('RC'!I48,'RC'!J48) -> 141653.49 | ... K33: =AVERAGE('RC'!K48,'RC'!L48) -> 154222
A34: Rimanenze magazzino medie | B34: =AVERAGE('RC'!B6,'RC'!C6) -> 124615 | C34: =AVERAGE('RC'!C6,'RC'!D6) -> 135911.57 | D34: =AVERAGE('RC'!D6,'RC'!E6) -> 143120.67 | E34: =AVERAGE('RC'!E6,'RC'!F6) -> 127459.79 | F34: =AVERAGE('RC'!F6,'RC'!G6) -> 120911.66 | G34: =AVERAGE('RC'!G6,'RC'!H6) -> 142660.63 | H34: =AVERAGE('RC'!H6,'RC'!I6) -> 144228.21 | I34: =AVERAGE('RC'!I6,'RC'!J6) -> 126816.17 | ... K34: =AVERAGE('RC'!K6,'RC'!L6) -> 127191.34
A35: Rimanenze magazzino finali | B35: ='RC'!B6 -> 131166 | C35: ='RC'!C6 -> 118064 | D35: ='RC'!D6 -> 153759.14 | E35: ='RC'!E6 -> 132482.19 | F35: ='RC'!F6 -> 122437.39 | G35: ='RC'!G6 -> 119385.93 | H35: ='RC'!H6 -> 165935.34 | I35: ='RC'!I6 -> 122521.08 | ... K35: ='RC'!K6 -> 127191.34
A36: Attività a BT | B36: =AVERAGE('RC'!B8:C8)+AVERAGE('RC'!B19:C19)+AVERAGE('RC'!B30:C30) -> 524998.5 | C36: =AVERAGE('RC'!C8:D8)+AVERAGE('RC'!C19:D19)+AVERAGE('RC'!C30:D30) -> 365263.36 | D36: =AVERAGE('RC'!D8:E8)+AVERAGE('RC'!D19:E19)+AVERAGE('RC'!D30:E30) -> 226113.39 | E36: =AVERAGE('RC'!E8:F8)+AVERAGE('RC'!E19:F19)+AVERAGE('RC'!E30:F30) -> 206385.4 | F36: =AVERAGE('RC'!F8:G8)+AVERAGE('RC'!F19:G19)+AVERAGE('RC'!F30:G30) -> 201192.46 | G36: =AVERAGE('RC'!G8:H8)+AVERAGE('RC'!G19:H19)+AVERAGE('RC'!G30:H30) -> 253874.74 | H36: =AVERAGE('RC'!H8:I8)+AVERAGE('RC'!H19:I19)+AVERAGE('RC'!H30:I30) -> 285343.9 | I36: =AVERAGE('RC'!I8:J8)+AVERAGE('RC'!I19:J19)+AVERAGE('RC'!I30:J30) -> 266313.68 | ... K36: =AVERAGE('RC'!K8:L8)+AVERAGE('RC'!K19:L19)+AVERAGE('RC'!K30:L30) -> 281017.5
